[2022-06-19 03:54:48,117] {taskinstance.py:1159} INFO - Dependencies all met for <TaskInstance: Job-pts.pts-Papple-iphone-xs-512gb-space-grau_h_6248 scheduled__2022-06-19T01:09:09.446748+00:00 [queued]>
[2022-06-19 03:54:48,128] {taskinstance.py:1159} INFO - Dependencies all met for <TaskInstance: Job-pts.pts-Papple-iphone-xs-512gb-space-grau_h_6248 scheduled__2022-06-19T01:09:09.446748+00:00 [queued]>
[2022-06-19 03:54:48,128] {taskinstance.py:1356} INFO - 
--------------------------------------------------------------------------------
[2022-06-19 03:54:48,128] {taskinstance.py:1357} INFO - Starting attempt 1 of 6
[2022-06-19 03:54:48,129] {taskinstance.py:1358} INFO - 
--------------------------------------------------------------------------------
[2022-06-19 03:54:48,150] {taskinstance.py:1377} INFO - Executing <Task(PythonOperator): pts-Papple-iphone-xs-512gb-space-grau_h_6248> on 2022-06-19 01:09:09.446748+00:00
[2022-06-19 03:54:48,155] {standard_task_runner.py:52} INFO - Started process 18045 to run task
[2022-06-19 03:54:48,158] {standard_task_runner.py:79} INFO - Running: ['airflow', 'tasks', 'run', 'Job-pts', 'pts-Papple-iphone-xs-512gb-space-grau_h_6248', 'scheduled__2022-06-19T01:09:09.446748+00:00', '--job-id', '499', '--raw', '--subdir', 'DAGS_FOLDER/docker_job/price_scale.py', '--cfg-path', '/tmp/tmpr0wbo297', '--error-file', '/tmp/tmpvqq697g0']
[2022-06-19 03:54:48,159] {standard_task_runner.py:80} INFO - Job 499: Subtask pts-Papple-iphone-xs-512gb-space-grau_h_6248
[2022-06-19 03:54:48,182] {warnings.py:110} WARNING - /home/airflow/.local/lib/python3.7/site-packages/airflow/configuration.py:525: DeprecationWarning: The sql_alchemy_conn option in [core] has been moved to the sql_alchemy_conn option in [database] - the old setting has been used, but please update your config.
  option = self._get_environment_variables(deprecated_key, deprecated_section, key, section)

[2022-06-19 03:54:48,259] {task_command.py:370} INFO - Running <TaskInstance: Job-pts.pts-Papple-iphone-xs-512gb-space-grau_h_6248 scheduled__2022-06-19T01:09:09.446748+00:00 [running]> on host 2d9e52ec85d2
[2022-06-19 03:54:48,492] {taskinstance.py:1571} INFO - Exporting the following env vars:
AIRFLOW_CTX_DAG_EMAIL=samuel.momoh-olle@asgoodasnew.com
AIRFLOW_CTX_DAG_OWNER=airflow
AIRFLOW_CTX_DAG_ID=Job-pts
AIRFLOW_CTX_TASK_ID=pts-Papple-iphone-xs-512gb-space-grau_h_6248
AIRFLOW_CTX_EXECUTION_DATE=2022-06-19T01:09:09.446748+00:00
AIRFLOW_CTX_TRY_NUMBER=1
AIRFLOW_CTX_DAG_RUN_ID=scheduled__2022-06-19T01:09:09.446748+00:00
[2022-06-19 03:56:01,841] {taskinstance.py:1889} ERROR - Task failed with exception
Traceback (most recent call last):
  File "/home/airflow/.local/lib/python3.7/site-packages/airflow/operators/python.py", line 171, in execute
    return_value = self.execute_callable()
  File "/home/airflow/.local/lib/python3.7/site-packages/airflow/operators/python.py", line 189, in execute_callable
    return self.python_callable(*self.op_args, **self.op_kwargs)
  File "/opt/airflow/dags/docker_job/price_scale.py", line 115, in test
    ppd = ProductPriceData(driver=webdriver.Chrome(executable_path="dags/docker_job/chromedriver", options=options))
  File "/home/airflow/.local/lib/python3.7/site-packages/selenium/webdriver/chrome/webdriver.py", line 73, in __init__
    service_log_path, service, keep_alive)
  File "/home/airflow/.local/lib/python3.7/site-packages/selenium/webdriver/chromium/webdriver.py", line 98, in __init__
    options=options)
  File "/home/airflow/.local/lib/python3.7/site-packages/selenium/webdriver/remote/webdriver.py", line 275, in __init__
    self.start_session(capabilities, browser_profile)
  File "/home/airflow/.local/lib/python3.7/site-packages/selenium/webdriver/remote/webdriver.py", line 365, in start_session
    response = self.execute(Command.NEW_SESSION, parameters)
  File "/home/airflow/.local/lib/python3.7/site-packages/selenium/webdriver/remote/webdriver.py", line 430, in execute
    self.error_handler.check_response(response)
  File "/home/airflow/.local/lib/python3.7/site-packages/selenium/webdriver/remote/errorhandler.py", line 247, in check_response
    raise exception_class(message, screen, stacktrace)
selenium.common.exceptions.WebDriverException: Message: unknown error: DevToolsActivePort file doesn't exist
Stacktrace:
#0 0x562473c34f33 <unknown>
#1 0x56247397f118 <unknown>
#2 0x5624739a5282 <unknown>
#3 0x5624739a17c6 <unknown>
#4 0x56247399dd5a <unknown>
#5 0x5624739d8d3a <unknown>
#6 0x5624739d2e63 <unknown>
#7 0x5624739a882a <unknown>
#8 0x5624739a9985 <unknown>
#9 0x562473c794cd <unknown>
#10 0x562473c7d5ec <unknown>
#11 0x562473c6371e <unknown>
#12 0x562473c7e238 <unknown>
#13 0x562473c58870 <unknown>
#14 0x562473c9a608 <unknown>
#15 0x562473c9a788 <unknown>
#16 0x562473cb4f1d <unknown>
#17 0x7f1d27178ea7 <unknown>

[2022-06-19 03:58:07,325] {taskinstance.py:1400} INFO - Marking task as UP_FOR_RETRY. dag_id=Job-pts, task_id=pts-Papple-iphone-xs-512gb-space-grau_h_6248, execution_date=20220619T010909, start_date=20220619T035448, end_date=20220619T035807
[2022-06-19 03:58:07,438] {standard_task_runner.py:97} ERROR - Failed to execute job 499 for task pts-Papple-iphone-xs-512gb-space-grau_h_6248 (Message: unknown error: DevToolsActivePort file doesn't exist
Stacktrace:
#0 0x562473c34f33 <unknown>
#1 0x56247397f118 <unknown>
#2 0x5624739a5282 <unknown>
#3 0x5624739a17c6 <unknown>
#4 0x56247399dd5a <unknown>
#5 0x5624739d8d3a <unknown>
#6 0x5624739d2e63 <unknown>
#7 0x5624739a882a <unknown>
#8 0x5624739a9985 <unknown>
#9 0x562473c794cd <unknown>
#10 0x562473c7d5ec <unknown>
#11 0x562473c6371e <unknown>
#12 0x562473c7e238 <unknown>
#13 0x562473c58870 <unknown>
#14 0x562473c9a608 <unknown>
#15 0x562473c9a788 <unknown>
#16 0x562473cb4f1d <unknown>
#17 0x7f1d27178ea7 <unknown>
; 18045)
[2022-06-19 03:58:07,519] {local_task_job.py:156} INFO - Task exited with return code 1
[2022-06-19 03:58:08,725] {local_task_job.py:273} INFO - 0 downstream tasks scheduled from follow-on schedule check
