[2022-06-12 02:08:03,581] {taskinstance.py:1159} INFO - Dependencies all met for <TaskInstance: T-dbt-job-dimensions.dbt_clone_and_transform-dimensions manual__2022-06-12T02:08:02.370545+00:00 [queued]>
[2022-06-12 02:08:03,592] {taskinstance.py:1159} INFO - Dependencies all met for <TaskInstance: T-dbt-job-dimensions.dbt_clone_and_transform-dimensions manual__2022-06-12T02:08:02.370545+00:00 [queued]>
[2022-06-12 02:08:03,593] {taskinstance.py:1356} INFO - 
--------------------------------------------------------------------------------
[2022-06-12 02:08:03,593] {taskinstance.py:1357} INFO - Starting attempt 1 of 2
[2022-06-12 02:08:03,593] {taskinstance.py:1358} INFO - 
--------------------------------------------------------------------------------
[2022-06-12 02:08:03,613] {taskinstance.py:1377} INFO - Executing <Task(BashOperator): dbt_clone_and_transform-dimensions> on 2022-06-12 02:08:02.370545+00:00
[2022-06-12 02:08:03,618] {standard_task_runner.py:52} INFO - Started process 2186 to run task
[2022-06-12 02:08:03,622] {standard_task_runner.py:79} INFO - Running: ['airflow', 'tasks', 'run', 'T-dbt-job-dimensions', 'dbt_clone_and_transform-dimensions', 'manual__2022-06-12T02:08:02.370545+00:00', '--job-id', '69', '--raw', '--subdir', 'DAGS_FOLDER/docker_job/dbt_model.py', '--cfg-path', '/tmp/tmpj8gm9_il', '--error-file', '/tmp/tmpcv7zr5vt']
[2022-06-12 02:08:03,623] {standard_task_runner.py:80} INFO - Job 69: Subtask dbt_clone_and_transform-dimensions
[2022-06-12 02:08:03,679] {task_command.py:370} INFO - Running <TaskInstance: T-dbt-job-dimensions.dbt_clone_and_transform-dimensions manual__2022-06-12T02:08:02.370545+00:00 [running]> on host e926c0944008
[2022-06-12 02:08:03,747] {taskinstance.py:1571} INFO - Exporting the following env vars:
AIRFLOW_CTX_DAG_EMAIL=samuelolle@yahoo.com
AIRFLOW_CTX_DAG_OWNER=airflow
AIRFLOW_CTX_DAG_ID=T-dbt-job-dimensions
AIRFLOW_CTX_TASK_ID=dbt_clone_and_transform-dimensions
AIRFLOW_CTX_EXECUTION_DATE=2022-06-12T02:08:02.370545+00:00
AIRFLOW_CTX_TRY_NUMBER=1
AIRFLOW_CTX_DAG_RUN_ID=manual__2022-06-12T02:08:02.370545+00:00
[2022-06-12 02:08:03,748] {subprocess.py:62} INFO - Tmp dir root location: 
 /tmp
[2022-06-12 02:08:03,748] {subprocess.py:74} INFO - Running command: ['bash', '-c', " rm -rf /tmp/dimensions && mkdir /tmp/dimensions                            && cp -r /tmp/dbt /tmp/dimensions/dbt                             && cd /tmp/dimensions/dbt && python3 -m venv venv                             && export PIP_USER=false                             && *** /tmp/dimensions/dbt/venv/bin/activate                             && pip  install --quiet --upgrade pip setuptools                             && pip3 install --quiet 'MarkupSafe<=2.0.1' 'dbt-postgres' 'dbt-core'                             && dbt --version && deactivate                             && cd /tmp/dimensions/dbt && *** /tmp/dimensions/dbt/venv/bin/activate                             && dbt deps --profiles-dir /tmp/dimensions/dbt/ && dbt seed --profiles-dir /tmp/dimensions/dbt/                             && dbt run --models dimensions --profiles-dir /tmp/dimensions/dbt/"]
[2022-06-12 02:08:03,760] {subprocess.py:85} INFO - Output:
[2022-06-12 02:08:41,124] {subprocess.py:92} INFO - Core:
[2022-06-12 02:08:41,124] {subprocess.py:92} INFO -   - installed: 1.1.0
[2022-06-12 02:08:41,125] {subprocess.py:92} INFO -   - latest:    1.1.0 - [32mUp to date![0m
[2022-06-12 02:08:41,125] {subprocess.py:92} INFO - 
[2022-06-12 02:08:41,125] {subprocess.py:92} INFO - Plugins:
[2022-06-12 02:08:41,125] {subprocess.py:92} INFO -   - postgres: 1.1.0 - [32mUp to date![0m
[2022-06-12 02:08:43,798] {subprocess.py:92} INFO - [0m02:08:43  Running with dbt=1.1.0
[2022-06-12 02:08:43,800] {subprocess.py:92} INFO - [0m02:08:43  Warning: No packages were found in packages.yml
[2022-06-12 02:08:46,683] {subprocess.py:92} INFO - [0m02:08:46  Running with dbt=1.1.0
[2022-06-12 02:08:46,697] {subprocess.py:92} INFO - [0m02:08:46  Partial parse save file not found. Starting full parse.
[2022-06-12 02:08:47,329] {subprocess.py:92} INFO - [0m02:08:47  [WARNING]: Configuration paths exist in your dbt_project.yml file which do not apply to any re***s.
[2022-06-12 02:08:47,329] {subprocess.py:92} INFO - There are 1 unused configuration paths:
[2022-06-12 02:08:47,329] {subprocess.py:92} INFO - - seeds.SAM
[2022-06-12 02:08:47,329] {subprocess.py:92} INFO - 
[2022-06-12 02:08:47,349] {subprocess.py:92} INFO - [0m02:08:47  Found 5 models, 6 tests, 0 snapshots, 0 analyses, 171 macros, 6 operations, 0 seed files, 4 ***s, 0 exposures, 0 metrics
[2022-06-12 02:08:47,351] {subprocess.py:92} INFO - [0m02:08:47
[2022-06-12 02:08:47,351] {subprocess.py:92} INFO - [0m02:08:47  [WARNING]: Nothing to do. Try checking your model configs and model specification args
[2022-06-12 02:08:47,357] {subprocess.py:92} INFO - [0m02:08:47
[2022-06-12 02:08:47,357] {subprocess.py:92} INFO - [0m02:08:47  Completed successfully
[2022-06-12 02:08:47,357] {subprocess.py:92} INFO - [0m02:08:47
[2022-06-12 02:08:47,358] {subprocess.py:92} INFO - [0m02:08:47  Done. PASS=0 WARN=0 ERROR=0 SKIP=0 TOTAL=0
[2022-06-12 02:08:50,233] {subprocess.py:92} INFO - [0m02:08:50  Running with dbt=1.1.0
[2022-06-12 02:08:50,265] {subprocess.py:92} INFO - [0m02:08:50  [WARNING]: Configuration paths exist in your dbt_project.yml file which do not apply to any re***s.
[2022-06-12 02:08:50,265] {subprocess.py:92} INFO - There are 1 unused configuration paths:
[2022-06-12 02:08:50,266] {subprocess.py:92} INFO - - seeds.SAM
[2022-06-12 02:08:50,266] {subprocess.py:92} INFO - 
[2022-06-12 02:08:50,279] {subprocess.py:92} INFO - [0m02:08:50  Found 5 models, 6 tests, 0 snapshots, 0 analyses, 171 macros, 6 operations, 0 seed files, 4 ***s, 0 exposures, 0 metrics
[2022-06-12 02:08:50,281] {subprocess.py:92} INFO - [0m02:08:50
[2022-06-12 02:08:50,350] {subprocess.py:92} INFO - [0m02:08:50  Concurrency: 4 threads (target='dev')
[2022-06-12 02:08:50,350] {subprocess.py:92} INFO - [0m02:08:50
[2022-06-12 02:08:50,357] {subprocess.py:92} INFO - [0m02:08:50  1 of 2 START table model analytics_objects_analytics_dim.dim_date .............. [RUN]
[2022-06-12 02:08:50,358] {subprocess.py:92} INFO - [0m02:08:50  2 of 2 START incremental model analytics_objects_analytics_dim.dim_walls ....... [RUN]
[2022-06-12 02:08:50,447] {subprocess.py:92} INFO - [0m02:08:50  2 of 2 ERROR creating incremental model analytics_objects_analytics_dim.dim_walls  [ERROR in 0.09s]
[2022-06-12 02:08:50,482] {subprocess.py:92} INFO - [0m02:08:50  1 of 2 OK created table model analytics_objects_analytics_dim.dim_date ......... [SELECT 546 in 0.12s]
[2022-06-12 02:08:50,563] {subprocess.py:92} INFO - [0m02:08:50
[2022-06-12 02:08:50,564] {subprocess.py:92} INFO - [0m02:08:50  Running 6 on-run-end hooks
[2022-06-12 02:08:50,570] {subprocess.py:92} INFO - [0m02:08:50  1 of 6 START hook: SAM.on-run-end.0 ............................................ [RUN]
[2022-06-12 02:08:50,573] {subprocess.py:92} INFO - [0m02:08:50  1 of 6 OK hook: SAM.on-run-end.0 ............................................... [ALTER DEFAULT PRIVILEGES in 0.00s]
[2022-06-12 02:08:50,578] {subprocess.py:92} INFO - [0m02:08:50  2 of 6 START hook: SAM.on-run-end.1 ............................................ [RUN]
[2022-06-12 02:08:50,581] {subprocess.py:92} INFO - [0m02:08:50  2 of 6 OK hook: SAM.on-run-end.1 ............................................... [ALTER DEFAULT PRIVILEGES in 0.00s]
[2022-06-12 02:08:50,587] {subprocess.py:92} INFO - [0m02:08:50  3 of 6 START hook: SAM.on-run-end.2 ............................................ [RUN]
[2022-06-12 02:08:50,591] {subprocess.py:92} INFO - [0m02:08:50  3 of 6 OK hook: SAM.on-run-end.2 ............................................... [ALTER DEFAULT PRIVILEGES in 0.00s]
[2022-06-12 02:08:50,594] {subprocess.py:92} INFO - [0m02:08:50  4 of 6 START hook: SAM.on-run-end.3 ............................................ [RUN]
[2022-06-12 02:08:50,599] {subprocess.py:92} INFO - [0m02:08:50  4 of 6 OK hook: SAM.on-run-end.3 ............................................... [ALTER DEFAULT PRIVILEGES in 0.00s]
[2022-06-12 02:08:50,603] {subprocess.py:92} INFO - [0m02:08:50  5 of 6 START hook: SAM.on-run-end.4 ............................................ [RUN]
[2022-06-12 02:08:50,605] {subprocess.py:92} INFO - [0m02:08:50  5 of 6 OK hook: SAM.on-run-end.4 ............................................... [ALTER DEFAULT PRIVILEGES in 0.00s]
[2022-06-12 02:08:50,609] {subprocess.py:92} INFO - [0m02:08:50  6 of 6 START hook: SAM.on-run-end.5 ............................................ [RUN]
[2022-06-12 02:08:50,612] {subprocess.py:92} INFO - [0m02:08:50  6 of 6 OK hook: SAM.on-run-end.5 ............................................... [ALTER DEFAULT PRIVILEGES in 0.00s]
[2022-06-12 02:08:50,612] {subprocess.py:92} INFO - [0m02:08:50
[2022-06-12 02:08:50,613] {subprocess.py:92} INFO - [0m02:08:50
[2022-06-12 02:08:50,613] {subprocess.py:92} INFO - [0m02:08:50  Finished running 1 incremental model, 1 table model, 6 hooks in 0.33s.
[2022-06-12 02:08:50,621] {subprocess.py:92} INFO - [0m02:08:50
[2022-06-12 02:08:50,622] {subprocess.py:92} INFO - [0m02:08:50  Completed with 1 error and 0 warnings:
[2022-06-12 02:08:50,622] {subprocess.py:92} INFO - [0m02:08:50
[2022-06-12 02:08:50,623] {subprocess.py:92} INFO - [0m02:08:50  Database Error in model dim_walls (models/dimensions/dim_walls.sql)
[2022-06-12 02:08:50,623] {subprocess.py:92} INFO - [0m02:08:50    relation "analytics_objects_analytics_dim.dim_walls" does not exist
[2022-06-12 02:08:50,623] {subprocess.py:92} INFO - [0m02:08:50    LINE 22: left join "target"."analytics_objects_analytics_dim"."dim_wa...
[2022-06-12 02:08:50,624] {subprocess.py:92} INFO - [0m02:08:50                       ^
[2022-06-12 02:08:50,625] {subprocess.py:92} INFO - [0m02:08:50    compiled SQL at target/run/SAM/models/dimensions/dim_walls.sql
[2022-06-12 02:08:50,625] {subprocess.py:92} INFO - [0m02:08:50
[2022-06-12 02:08:50,626] {subprocess.py:92} INFO - [0m02:08:50  Done. PASS=1 WARN=0 ERROR=1 SKIP=0 TOTAL=2
[2022-06-12 02:08:50,807] {subprocess.py:96} INFO - Command exited with return code 1
[2022-06-12 02:08:50,822] {taskinstance.py:1889} ERROR - Task failed with exception
Traceback (most recent call last):
  File "/home/airflow/.local/lib/python3.7/site-packages/airflow/operators/bash.py", line 195, in execute
    f'Bash command failed. The command returned a non-zero exit code {result.exit_code}.'
airflow.exceptions.AirflowException: Bash command failed. The command returned a non-zero exit code 1.
[2022-06-12 02:08:50,826] {taskinstance.py:1400} INFO - Marking task as UP_FOR_RETRY. dag_id=T-dbt-job-dimensions, task_id=dbt_clone_and_transform-dimensions, execution_date=20220612T020802, start_date=20220612T020803, end_date=20220612T020850
[2022-06-12 02:08:50,838] {standard_task_runner.py:97} ERROR - Failed to execute job 69 for task dbt_clone_and_transform-dimensions (Bash command failed. The command returned a non-zero exit code 1.; 2186)
[2022-06-12 02:08:50,851] {local_task_job.py:156} INFO - Task exited with return code 1
[2022-06-12 02:08:50,885] {local_task_job.py:273} INFO - 0 downstream tasks scheduled from follow-on schedule check
