[2022-06-11 18:19:03,034] {taskinstance.py:1159} INFO - Dependencies all met for <TaskInstance: T-dbt-job-objects.dbt_clone_and_transform-objects manual__2022-06-11T18:11:44.385614+00:00 [queued]>
[2022-06-11 18:19:03,042] {taskinstance.py:1159} INFO - Dependencies all met for <TaskInstance: T-dbt-job-objects.dbt_clone_and_transform-objects manual__2022-06-11T18:11:44.385614+00:00 [queued]>
[2022-06-11 18:19:03,042] {taskinstance.py:1356} INFO - 
--------------------------------------------------------------------------------
[2022-06-11 18:19:03,043] {taskinstance.py:1357} INFO - Starting attempt 1 of 2
[2022-06-11 18:19:03,043] {taskinstance.py:1358} INFO - 
--------------------------------------------------------------------------------
[2022-06-11 18:19:03,056] {taskinstance.py:1377} INFO - Executing <Task(BashOperator): dbt_clone_and_transform-objects> on 2022-06-11 18:11:44.385614+00:00
[2022-06-11 18:19:03,064] {standard_task_runner.py:52} INFO - Started process 1003 to run task
[2022-06-11 18:19:03,067] {standard_task_runner.py:79} INFO - Running: ['airflow', 'tasks', 'run', 'T-dbt-job-objects', 'dbt_clone_and_transform-objects', 'manual__2022-06-11T18:11:44.385614+00:00', '--job-id', '73', '--raw', '--subdir', 'DAGS_FOLDER/docker_job/dbt_test.py', '--cfg-path', '/tmp/tmpkti84ump', '--error-file', '/tmp/tmp5du4phyv']
[2022-06-11 18:19:03,068] {standard_task_runner.py:80} INFO - Job 73: Subtask dbt_clone_and_transform-objects
[2022-06-11 18:19:03,140] {task_command.py:370} INFO - Running <TaskInstance: T-dbt-job-objects.dbt_clone_and_transform-objects manual__2022-06-11T18:11:44.385614+00:00 [running]> on host d8836eb746ac
[2022-06-11 18:19:03,209] {taskinstance.py:1571} INFO - Exporting the following env vars:
AIRFLOW_CTX_DAG_EMAIL=samuelolle@yahoo.com
AIRFLOW_CTX_DAG_OWNER=airflow
AIRFLOW_CTX_DAG_ID=T-dbt-job-objects
AIRFLOW_CTX_TASK_ID=dbt_clone_and_transform-objects
AIRFLOW_CTX_EXECUTION_DATE=2022-06-11T18:11:44.385614+00:00
AIRFLOW_CTX_TRY_NUMBER=1
AIRFLOW_CTX_DAG_RUN_ID=manual__2022-06-11T18:11:44.385614+00:00
[2022-06-11 18:19:03,210] {subprocess.py:62} INFO - Tmp dir root location: 
 /tmp
[2022-06-11 18:19:03,210] {subprocess.py:74} INFO - Running command: ['bash', '-c', " rm -rf /tmp/objects && mkdir /tmp/objects                            && cp -r /tmp/dbt /tmp/objects/dbt                             && cd /tmp/objects/dbt && python3 -m venv venv                             && export PIP_USER=false                             && *** /tmp/objects/dbt/venv/bin/activate                             && pip  install --quiet --upgrade pip setuptools                             && pip3 install --quiet 'MarkupSafe<=2.0.1' 'dbt-postgres' 'dbt-core'                             && dbt --version && deactivate                             && cd /tmp/objects/dbt && *** /tmp/objects/dbt/venv/bin/activate                             && dbt deps --profiles-dir /tmp/objects/dbt/ && dbt seed --profiles-dir /tmp/objects/dbt/                             && dbt run --models objects --profiles-dir /tmp/objects/dbt/"]
[2022-06-11 18:19:03,222] {subprocess.py:85} INFO - Output:
[2022-06-11 18:19:43,476] {subprocess.py:92} INFO - Core:
[2022-06-11 18:19:43,477] {subprocess.py:92} INFO -   - installed: 1.1.0
[2022-06-11 18:19:43,477] {subprocess.py:92} INFO -   - latest:    1.1.0 - [32mUp to date![0m
[2022-06-11 18:19:43,477] {subprocess.py:92} INFO - 
[2022-06-11 18:19:43,477] {subprocess.py:92} INFO - Plugins:
[2022-06-11 18:19:43,477] {subprocess.py:92} INFO -   - postgres: 1.1.0 - [32mUp to date![0m
[2022-06-11 18:19:47,133] {subprocess.py:92} INFO - [0m18:19:47  Running with dbt=1.1.0
[2022-06-11 18:19:47,135] {subprocess.py:92} INFO - [0m18:19:47  Warning: No packages were found in packages.yml
[2022-06-11 18:19:50,840] {subprocess.py:92} INFO - [0m18:19:50  Running with dbt=1.1.0
[2022-06-11 18:19:50,858] {subprocess.py:92} INFO - [0m18:19:50  Partial parse save file not found. Starting full parse.
[2022-06-11 18:19:51,584] {subprocess.py:92} INFO - [0m18:19:51  [WARNING]: Configuration paths exist in your dbt_project.yml file which do not apply to any re***s.
[2022-06-11 18:19:51,584] {subprocess.py:92} INFO - There are 1 unused configuration paths:
[2022-06-11 18:19:51,584] {subprocess.py:92} INFO - - seeds.SAM
[2022-06-11 18:19:51,584] {subprocess.py:92} INFO - 
[2022-06-11 18:19:51,599] {subprocess.py:92} INFO - [0m18:19:51  Found 4 models, 6 tests, 0 snapshots, 0 analyses, 171 macros, 4 operations, 0 seed files, 4 ***s, 0 exposures, 0 metrics
[2022-06-11 18:19:51,601] {subprocess.py:92} INFO - [0m18:19:51
[2022-06-11 18:19:51,602] {subprocess.py:92} INFO - [0m18:19:51  [WARNING]: Nothing to do. Try checking your model configs and model specification args
[2022-06-11 18:19:51,613] {subprocess.py:92} INFO - [0m18:19:51
[2022-06-11 18:19:51,613] {subprocess.py:92} INFO - [0m18:19:51  Completed successfully
[2022-06-11 18:19:51,614] {subprocess.py:92} INFO - [0m18:19:51
[2022-06-11 18:19:51,614] {subprocess.py:92} INFO - [0m18:19:51  Done. PASS=0 WARN=0 ERROR=0 SKIP=0 TOTAL=0
[2022-06-11 18:19:55,159] {subprocess.py:92} INFO - [0m18:19:55  Running with dbt=1.1.0
[2022-06-11 18:19:55,198] {subprocess.py:92} INFO - [0m18:19:55  [WARNING]: Configuration paths exist in your dbt_project.yml file which do not apply to any re***s.
[2022-06-11 18:19:55,198] {subprocess.py:92} INFO - There are 1 unused configuration paths:
[2022-06-11 18:19:55,198] {subprocess.py:92} INFO - - seeds.SAM
[2022-06-11 18:19:55,198] {subprocess.py:92} INFO - 
[2022-06-11 18:19:55,218] {subprocess.py:92} INFO - [0m18:19:55  Found 4 models, 6 tests, 0 snapshots, 0 analyses, 171 macros, 4 operations, 0 seed files, 4 ***s, 0 exposures, 0 metrics
[2022-06-11 18:19:55,220] {subprocess.py:92} INFO - [0m18:19:55
[2022-06-11 18:19:55,349] {subprocess.py:92} INFO - [0m18:19:55  Concurrency: 4 threads (target='dev')
[2022-06-11 18:19:55,349] {subprocess.py:92} INFO - [0m18:19:55
[2022-06-11 18:19:55,360] {subprocess.py:92} INFO - [0m18:19:55  1 of 1 START table model analytics_object.obj_walls ............................ [RUN]
[2022-06-11 18:19:55,417] {subprocess.py:92} INFO - [0m18:19:55  1 of 1 ERROR creating table model analytics_object.obj_walls ................... [ERROR in 0.06s]
[2022-06-11 18:19:55,470] {subprocess.py:92} INFO - [0m18:19:55
[2022-06-11 18:19:55,475] {subprocess.py:92} INFO - [0m18:19:55  Running 4 on-run-end hooks
[2022-06-11 18:19:55,482] {subprocess.py:92} INFO - [0m18:19:55  1 of 4 START hook: SAM.on-run-end.0 ............................................ [RUN]
[2022-06-11 18:19:55,486] {subprocess.py:92} INFO - [0m18:19:55  1 of 4 OK hook: SAM.on-run-end.0 ............................................... [ALTER DEFAULT PRIVILEGES in 0.00s]
[2022-06-11 18:19:55,493] {subprocess.py:92} INFO - [0m18:19:55  2 of 4 START hook: SAM.on-run-end.1 ............................................ [RUN]
[2022-06-11 18:19:55,495] {subprocess.py:92} INFO - [0m18:19:55  2 of 4 OK hook: SAM.on-run-end.1 ............................................... [ALTER DEFAULT PRIVILEGES in 0.00s]
[2022-06-11 18:19:55,501] {subprocess.py:92} INFO - [0m18:19:55  3 of 4 START hook: SAM.on-run-end.2 ............................................ [RUN]
[2022-06-11 18:19:55,507] {subprocess.py:92} INFO - [0m18:19:55  3 of 4 OK hook: SAM.on-run-end.2 ............................................... [ALTER DEFAULT PRIVILEGES in 0.01s]
[2022-06-11 18:19:55,512] {subprocess.py:92} INFO - [0m18:19:55  4 of 4 START hook: SAM.on-run-end.3 ............................................ [RUN]
[2022-06-11 18:19:55,514] {subprocess.py:92} INFO - [0m18:19:55  4 of 4 OK hook: SAM.on-run-end.3 ............................................... [ALTER DEFAULT PRIVILEGES in 0.00s]
[2022-06-11 18:19:55,515] {subprocess.py:92} INFO - [0m18:19:55
[2022-06-11 18:19:55,515] {subprocess.py:92} INFO - [0m18:19:55
[2022-06-11 18:19:55,516] {subprocess.py:92} INFO - [0m18:19:55  Finished running 1 table model, 4 hooks in 0.30s.
[2022-06-11 18:19:55,526] {subprocess.py:92} INFO - [0m18:19:55
[2022-06-11 18:19:55,526] {subprocess.py:92} INFO - [0m18:19:55  Completed with 1 error and 0 warnings:
[2022-06-11 18:19:55,526] {subprocess.py:92} INFO - [0m18:19:55
[2022-06-11 18:19:55,527] {subprocess.py:92} INFO - [0m18:19:55  Database Error in model obj_walls (models/objects/obj_walls.sql)
[2022-06-11 18:19:55,527] {subprocess.py:92} INFO - [0m18:19:55    relation "analytics_object.walls_cdc" does not exist
[2022-06-11 18:19:55,527] {subprocess.py:92} INFO - [0m18:19:55    LINE 6:     select * from "target"."analytics_object"."walls_cdc"
[2022-06-11 18:19:55,528] {subprocess.py:92} INFO - [0m18:19:55                              ^
[2022-06-11 18:19:55,529] {subprocess.py:92} INFO - [0m18:19:55    compiled SQL at target/run/SAM/models/objects/obj_walls.sql
[2022-06-11 18:19:55,529] {subprocess.py:92} INFO - [0m18:19:55
[2022-06-11 18:19:55,530] {subprocess.py:92} INFO - [0m18:19:55  Done. PASS=0 WARN=0 ERROR=1 SKIP=0 TOTAL=1
[2022-06-11 18:19:55,868] {subprocess.py:96} INFO - Command exited with return code 1
[2022-06-11 18:19:55,886] {taskinstance.py:1889} ERROR - Task failed with exception
Traceback (most recent call last):
  File "/home/airflow/.local/lib/python3.7/site-packages/airflow/operators/bash.py", line 195, in execute
    f'Bash command failed. The command returned a non-zero exit code {result.exit_code}.'
airflow.exceptions.AirflowException: Bash command failed. The command returned a non-zero exit code 1.
[2022-06-11 18:19:55,892] {taskinstance.py:1400} INFO - Marking task as UP_FOR_RETRY. dag_id=T-dbt-job-objects, task_id=dbt_clone_and_transform-objects, execution_date=20220611T181144, start_date=20220611T181903, end_date=20220611T181955
[2022-06-11 18:19:55,909] {standard_task_runner.py:97} ERROR - Failed to execute job 73 for task dbt_clone_and_transform-objects (Bash command failed. The command returned a non-zero exit code 1.; 1003)
[2022-06-11 18:19:55,949] {local_task_job.py:156} INFO - Task exited with return code 1
[2022-06-11 18:19:56,000] {local_task_job.py:273} INFO - 0 downstream tasks scheduled from follow-on schedule check
