[2022-06-16 21:24:33,052] {taskinstance.py:1159} INFO - Dependencies all met for <TaskInstance: Job-price_test_scale.price_test_scale-apple-iphone-x-256gb-space-grau_h_5145 scheduled__2022-06-16T18:45:53.419457+00:00 [queued]>
[2022-06-16 21:24:35,628] {taskinstance.py:1159} INFO - Dependencies all met for <TaskInstance: Job-price_test_scale.price_test_scale-apple-iphone-x-256gb-space-grau_h_5145 scheduled__2022-06-16T18:45:53.419457+00:00 [queued]>
[2022-06-16 21:24:35,634] {taskinstance.py:1356} INFO - 
--------------------------------------------------------------------------------
[2022-06-16 21:24:35,634] {taskinstance.py:1357} INFO - Starting attempt 1 of 6
[2022-06-16 21:24:35,634] {taskinstance.py:1358} INFO - 
--------------------------------------------------------------------------------
[2022-06-16 21:24:42,640] {taskinstance.py:1377} INFO - Executing <Task(PythonOperator): price_test_scale-apple-iphone-x-256gb-space-grau_h_5145> on 2022-06-16 18:45:53.419457+00:00
[2022-06-16 21:24:45,121] {standard_task_runner.py:52} INFO - Started process 9858 to run task
[2022-06-16 21:24:46,574] {standard_task_runner.py:79} INFO - Running: ['airflow', 'tasks', 'run', 'Job-price_test_scale', 'price_test_scale-apple-iphone-x-256gb-space-grau_h_5145', 'scheduled__2022-06-16T18:45:53.419457+00:00', '--job-id', '189', '--raw', '--subdir', 'DAGS_FOLDER/docker_job/price_test_scale.py', '--cfg-path', '/tmp/tmpcpad5lb7', '--error-file', '/tmp/tmpy1ouez0_']
[2022-06-16 21:24:47,801] {standard_task_runner.py:80} INFO - Job 189: Subtask price_test_scale-apple-iphone-x-256gb-space-grau_h_5145
[2022-06-16 21:26:19,275] {warnings.py:110} WARNING - /home/airflow/.local/lib/python3.7/site-packages/airflow/configuration.py:525: DeprecationWarning: The sql_alchemy_conn option in [core] has been moved to the sql_alchemy_conn option in [database] - the old setting has been used, but please update your config.
  option = self._get_environment_variables(deprecated_key, deprecated_section, key, section)

[2022-06-16 21:26:47,834] {standard_task_runner.py:97} ERROR - Failed to execute job 189 for task price_test_scale-apple-iphone-x-256gb-space-grau_h_5145 ((psycopg2.OperationalError) could not translate host name "postgres_source" to address: Temporary failure in name resolution

(Background on this error at: http://sqlalche.me/e/14/e3q8); 9858)
[2022-06-16 21:26:44,208] {base_job.py:229} ERROR - LocalTaskJob heartbeat got an exception
Traceback (most recent call last):
  File "/home/airflow/.local/lib/python3.7/site-packages/sqlalchemy/engine/base.py", line 3141, in _wrap_pool_connect
    return fn()
  File "/home/airflow/.local/lib/python3.7/site-packages/sqlalchemy/pool/base.py", line 301, in connect
    return _ConnectionFairy._checkout(self)
  File "/home/airflow/.local/lib/python3.7/site-packages/sqlalchemy/pool/base.py", line 755, in _checkout
    fairy = _ConnectionRecord.checkout(pool)
  File "/home/airflow/.local/lib/python3.7/site-packages/sqlalchemy/pool/base.py", line 419, in checkout
    rec = pool._do_get()
  File "/home/airflow/.local/lib/python3.7/site-packages/sqlalchemy/pool/impl.py", line 259, in _do_get
    return self._create_connection()
  File "/home/airflow/.local/lib/python3.7/site-packages/sqlalchemy/pool/base.py", line 247, in _create_connection
    return _ConnectionRecord(self)
  File "/home/airflow/.local/lib/python3.7/site-packages/sqlalchemy/pool/base.py", line 362, in __init__
    self.__connect(first_connect_check=True)
  File "/home/airflow/.local/lib/python3.7/site-packages/sqlalchemy/pool/base.py", line 605, in __connect
    pool.logger.debug("Error on connect(): %s", e)
  File "/home/airflow/.local/lib/python3.7/site-packages/sqlalchemy/util/langhelpers.py", line 72, in __exit__
    with_traceback=exc_tb,
  File "/home/airflow/.local/lib/python3.7/site-packages/sqlalchemy/util/compat.py", line 211, in raise_
    raise exception
  File "/home/airflow/.local/lib/python3.7/site-packages/sqlalchemy/pool/base.py", line 599, in __connect
    connection = pool._invoke_creator(self)
  File "/home/airflow/.local/lib/python3.7/site-packages/sqlalchemy/engine/create.py", line 578, in connect
    return dialect.connect(*cargs, **cparams)
  File "/home/airflow/.local/lib/python3.7/site-packages/sqlalchemy/engine/default.py", line 583, in connect
    return self.dbapi.connect(*cargs, **cparams)
  File "/home/airflow/.local/lib/python3.7/site-packages/psycopg2/__init__.py", line 122, in connect
    conn = _connect(dsn, connection_factory=connection_factory, **kwasync)
psycopg2.OperationalError: could not translate host name "postgres_***" to address: Temporary failure in name resolution


The above exception was the direct cause of the following exception:

Traceback (most recent call last):
  File "/home/airflow/.local/lib/python3.7/site-packages/airflow/jobs/base_job.py", line 219, in heartbeat
    session.merge(self)
  File "/home/airflow/.local/lib/python3.7/site-packages/sqlalchemy/orm/session.py", line 2877, in merge
    _resolve_conflict_map=_resolve_conflict_map,
  File "/home/airflow/.local/lib/python3.7/site-packages/sqlalchemy/orm/session.py", line 2950, in _merge
    merged = self.get(mapper.class_, key[1], identity_token=key[2])
  File "/home/airflow/.local/lib/python3.7/site-packages/sqlalchemy/orm/session.py", line 2702, in get
    identity_token=identity_token,
  File "/home/airflow/.local/lib/python3.7/site-packages/sqlalchemy/orm/session.py", line 2800, in _get_impl
    load_options=load_options,
  File "/home/airflow/.local/lib/python3.7/site-packages/sqlalchemy/orm/loading.py", line 535, in load_on_pk_identity
    bind_arguments=bind_arguments,
  File "/home/airflow/.local/lib/python3.7/site-packages/sqlalchemy/orm/session.py", line 1669, in execute
    conn = self._connection_for_bind(bind, close_with_result=True)
  File "/home/airflow/.local/lib/python3.7/site-packages/sqlalchemy/orm/session.py", line 1520, in _connection_for_bind
    engine, execution_options
  File "/home/airflow/.local/lib/python3.7/site-packages/sqlalchemy/orm/session.py", line 747, in _connection_for_bind
    conn = bind.connect()
  File "/home/airflow/.local/lib/python3.7/site-packages/sqlalchemy/engine/base.py", line 3095, in connect
    return self._connection_cls(self, close_with_result=close_with_result)
  File "/home/airflow/.local/lib/python3.7/site-packages/sqlalchemy/engine/base.py", line 91, in __init__
    else engine.raw_connection()
  File "/home/airflow/.local/lib/python3.7/site-packages/sqlalchemy/engine/base.py", line 3174, in raw_connection
    return self._wrap_pool_connect(self.pool.connect, _connection)
  File "/home/airflow/.local/lib/python3.7/site-packages/sqlalchemy/engine/base.py", line 3145, in _wrap_pool_connect
    e, dialect, self
  File "/home/airflow/.local/lib/python3.7/site-packages/sqlalchemy/engine/base.py", line 2004, in _handle_dbapi_exception_noconnection
    sqlalchemy_exception, with_traceback=exc_info[2], from_=e
  File "/home/airflow/.local/lib/python3.7/site-packages/sqlalchemy/util/compat.py", line 211, in raise_
    raise exception
  File "/home/airflow/.local/lib/python3.7/site-packages/sqlalchemy/engine/base.py", line 3141, in _wrap_pool_connect
    return fn()
  File "/home/airflow/.local/lib/python3.7/site-packages/sqlalchemy/pool/base.py", line 301, in connect
    return _ConnectionFairy._checkout(self)
  File "/home/airflow/.local/lib/python3.7/site-packages/sqlalchemy/pool/base.py", line 755, in _checkout
    fairy = _ConnectionRecord.checkout(pool)
  File "/home/airflow/.local/lib/python3.7/site-packages/sqlalchemy/pool/base.py", line 419, in checkout
    rec = pool._do_get()
  File "/home/airflow/.local/lib/python3.7/site-packages/sqlalchemy/pool/impl.py", line 259, in _do_get
    return self._create_connection()
  File "/home/airflow/.local/lib/python3.7/site-packages/sqlalchemy/pool/base.py", line 247, in _create_connection
    return _ConnectionRecord(self)
  File "/home/airflow/.local/lib/python3.7/site-packages/sqlalchemy/pool/base.py", line 362, in __init__
    self.__connect(first_connect_check=True)
  File "/home/airflow/.local/lib/python3.7/site-packages/sqlalchemy/pool/base.py", line 605, in __connect
    pool.logger.debug("Error on connect(): %s", e)
  File "/home/airflow/.local/lib/python3.7/site-packages/sqlalchemy/util/langhelpers.py", line 72, in __exit__
    with_traceback=exc_tb,
  File "/home/airflow/.local/lib/python3.7/site-packages/sqlalchemy/util/compat.py", line 211, in raise_
    raise exception
  File "/home/airflow/.local/lib/python3.7/site-packages/sqlalchemy/pool/base.py", line 599, in __connect
    connection = pool._invoke_creator(self)
  File "/home/airflow/.local/lib/python3.7/site-packages/sqlalchemy/engine/create.py", line 578, in connect
    return dialect.connect(*cargs, **cparams)
  File "/home/airflow/.local/lib/python3.7/site-packages/sqlalchemy/engine/default.py", line 583, in connect
    return self.dbapi.connect(*cargs, **cparams)
  File "/home/airflow/.local/lib/python3.7/site-packages/psycopg2/__init__.py", line 122, in connect
    conn = _connect(dsn, connection_factory=connection_factory, **kwasync)
sqlalchemy.exc.OperationalError: (psycopg2.OperationalError) could not translate host name "postgres_***" to address: Temporary failure in name resolution

(Background on this error at: http://sqlalche.me/e/14/e3q8)
[2022-06-16 21:26:50,443] {local_task_job.py:144} ERROR - Heartbeat time limit exceeded!
