[2022-06-19 17:55:34,419] {taskinstance.py:1159} INFO - Dependencies all met for <TaskInstance: Job-price_test_scale.price_test_scale-apple-iphone-xs-512gb-space-grau_h_6248 scheduled__2022-06-19T01:09:09.447981+00:00 [queued]>
[2022-06-19 17:55:34,641] {taskinstance.py:1159} INFO - Dependencies all met for <TaskInstance: Job-price_test_scale.price_test_scale-apple-iphone-xs-512gb-space-grau_h_6248 scheduled__2022-06-19T01:09:09.447981+00:00 [queued]>
[2022-06-19 17:55:34,641] {taskinstance.py:1356} INFO - 
--------------------------------------------------------------------------------
[2022-06-19 17:55:34,641] {taskinstance.py:1357} INFO - Starting attempt 5 of 6
[2022-06-19 17:55:34,641] {taskinstance.py:1358} INFO - 
--------------------------------------------------------------------------------
[2022-06-19 17:55:34,768] {taskinstance.py:1377} INFO - Executing <Task(PythonOperator): price_test_scale-apple-iphone-xs-512gb-space-grau_h_6248> on 2022-06-19 01:09:09.447981+00:00
[2022-06-19 17:55:34,804] {standard_task_runner.py:52} INFO - Started process 1333 to run task
[2022-06-19 17:55:35,361] {standard_task_runner.py:79} INFO - Running: ['airflow', 'tasks', 'run', 'Job-price_test_scale', 'price_test_scale-apple-iphone-xs-512gb-space-grau_h_6248', 'scheduled__2022-06-19T01:09:09.447981+00:00', '--job-id', '560', '--raw', '--subdir', 'DAGS_FOLDER/docker_job/price_test_scale.py', '--cfg-path', '/tmp/tmp3ndkn9k0', '--error-file', '/tmp/tmpz8fnrm6u']
[2022-06-19 17:55:35,362] {standard_task_runner.py:80} INFO - Job 560: Subtask price_test_scale-apple-iphone-xs-512gb-space-grau_h_6248
[2022-06-19 17:55:35,510] {warnings.py:110} WARNING - /home/airflow/.local/lib/python3.7/site-packages/airflow/configuration.py:525: DeprecationWarning: The sql_alchemy_conn option in [core] has been moved to the sql_alchemy_conn option in [database] - the old setting has been used, but please update your config.
  option = self._get_environment_variables(deprecated_key, deprecated_section, key, section)

[2022-06-19 17:55:35,879] {task_command.py:370} INFO - Running <TaskInstance: Job-price_test_scale.price_test_scale-apple-iphone-xs-512gb-space-grau_h_6248 scheduled__2022-06-19T01:09:09.447981+00:00 [running]> on host 2d9e52ec85d2
[2022-06-19 17:55:36,287] {taskinstance.py:1571} INFO - Exporting the following env vars:
AIRFLOW_CTX_DAG_EMAIL=samuel.momoh-olle@asgoodasnew.com
AIRFLOW_CTX_DAG_OWNER=airflow
AIRFLOW_CTX_DAG_ID=Job-price_test_scale
AIRFLOW_CTX_TASK_ID=price_test_scale-apple-iphone-xs-512gb-space-grau_h_6248
AIRFLOW_CTX_EXECUTION_DATE=2022-06-19T01:09:09.447981+00:00
AIRFLOW_CTX_TRY_NUMBER=5
AIRFLOW_CTX_DAG_RUN_ID=scheduled__2022-06-19T01:09:09.447981+00:00
[2022-06-19 17:55:36,298] {logging_mixin.py:115} INFO - /opt/airflow
[2022-06-19 17:55:37,509] {logging_mixin.py:115} INFO - https://www.handyverkauf.net/apple-iphone-xs-512gb-space-grau_h_6248
[2022-06-19 18:00:19,517] {local_task_job.py:84} ERROR - Received SIGTERM. Terminating subprocesses
[2022-06-19 18:00:19,545] {process_utils.py:129} INFO - Sending Signals.SIGTERM to group 1333. PIDs of all processes in the group: [1533, 2146, 2287, 2288, 2508, 2509, 2654, 3697, 2648, 1333]
[2022-06-19 18:00:19,546] {process_utils.py:80} INFO - Sending the signal Signals.SIGTERM to group 1333
[2022-06-19 18:00:19,546] {taskinstance.py:1541} ERROR - Received SIGTERM. Terminating subprocesses.
[2022-06-19 18:00:19,547] {logging_mixin.py:115} INFO - Task received SIGTERM signal
[2022-06-19 18:00:19,566] {connectionpool.py:811} WARNING - Retrying (Retry(total=2, connect=None, read=None, redirect=None, status=None)) after connection broken by 'ProtocolError('Connection aborted.', RemoteDisconnected('Remote end closed connection without response'))': /session/5adc68ba57271142ea01228bd147b45d
[2022-06-19 18:00:19,573] {connectionpool.py:811} WARNING - Retrying (Retry(total=1, connect=None, read=None, redirect=None, status=None)) after connection broken by 'NewConnectionError('<urllib3.connection.HTTPConnection object at 0x7f21cd436d10>: Failed to establish a new connection: [Errno 111] Connection refused')': /session/5adc68ba57271142ea01228bd147b45d
[2022-06-19 18:00:19,586] {connectionpool.py:811} WARNING - Retrying (Retry(total=0, connect=None, read=None, redirect=None, status=None)) after connection broken by 'NewConnectionError('<urllib3.connection.HTTPConnection object at 0x7f21cd436a90>: Failed to establish a new connection: [Errno 111] Connection refused')': /session/5adc68ba57271142ea01228bd147b45d
[2022-06-19 18:00:19,587] {logging_mixin.py:115} INFO - [('344,86 ', '/go/?anbieter=wirkaufens&id=6248', 'Apple iPhone XS 512GB space grau verkaufen', 'Gut', '2022-06-19'), ('254,28 ', '/go/?anbieter=rebuy&id=6248', 'Apple iPhone XS 512GB space grau verkaufen', 'Gut', '2022-06-19'), ('251,00 ', '/go/?anbieter=cleverbuy&id=6248', 'Apple iPhone XS 512GB space grau verkaufen', 'Gut', '2022-06-19'), ('247,14 ', '/go/?anbieter=clevertronic&id=6248', 'Apple iPhone XS 512GB space grau verkaufen', 'Gut', '2022-06-19'), ('246,00 ', '/go/?anbieter=myswooop&id=6248', 'Apple iPhone XS 512GB space grau verkaufen', 'Gut', '2022-06-19'), ('237,59 ', '/go/?anbieter=flip4new&id=6248', 'Apple iPhone XS 512GB space grau verkaufen', 'Gut', '2022-06-19'), ('215,99 ', '/go/?anbieter=zoxs&id=6248', 'Apple iPhone XS 512GB space grau verkaufen', 'Gut', '2022-06-19'), ('147,00 ', '/go/?anbieter=rezilla&id=6248', 'Apple iPhone XS 512GB space grau verkaufen', 'Gut', '2022-06-19')]
[2022-06-19 18:00:19,588] {python.py:173} INFO - Done. Returned value was: None
[2022-06-19 18:00:19,761] {process_utils.py:75} INFO - Process psutil.Process(pid=2508, status='terminated', started='17:55:38') (2508) terminated with exit code None
[2022-06-19 18:00:19,860] {process_utils.py:75} INFO - Process psutil.Process(pid=3697, status='terminated', started='17:55:41') (3697) terminated with exit code None
[2022-06-19 18:00:19,860] {process_utils.py:75} INFO - Process psutil.Process(pid=2648, status='terminated', started='17:55:39') (2648) terminated with exit code None
[2022-06-19 18:00:19,861] {process_utils.py:75} INFO - Process psutil.Process(pid=2509, status='terminated', started='17:55:38') (2509) terminated with exit code None
[2022-06-19 18:00:19,970] {process_utils.py:75} INFO - Process psutil.Process(pid=2288, status='terminated', started='17:55:38') (2288) terminated with exit code None
[2022-06-19 18:00:19,970] {process_utils.py:75} INFO - Process psutil.Process(pid=2146, status='terminated', started='17:55:37') (2146) terminated with exit code None
[2022-06-19 18:00:19,970] {process_utils.py:75} INFO - Process psutil.Process(pid=1533, status='terminated', started='17:55:37') (1533) terminated with exit code None
[2022-06-19 18:00:19,971] {process_utils.py:75} INFO - Process psutil.Process(pid=2287, status='terminated', started='17:55:38') (2287) terminated with exit code None
[2022-06-19 18:00:19,971] {process_utils.py:75} INFO - Process psutil.Process(pid=2654, status='terminated', started='17:55:39') (2654) terminated with exit code None
[2022-06-19 18:00:22,206] {taskinstance.py:1889} ERROR - Task failed with exception
Traceback (most recent call last):
  File "/home/airflow/.local/lib/python3.7/site-packages/sqlalchemy/engine/base.py", line 3141, in _wrap_pool_connect
    return fn()
  File "/home/airflow/.local/lib/python3.7/site-packages/sqlalchemy/pool/base.py", line 301, in connect
    return _ConnectionFairy._checkout(self)
  File "/home/airflow/.local/lib/python3.7/site-packages/sqlalchemy/pool/base.py", line 755, in _checkout
    fairy = _ConnectionRecord.checkout(pool)
  File "/home/airflow/.local/lib/python3.7/site-packages/sqlalchemy/pool/base.py", line 419, in checkout
    rec = pool._do_get()
  File "/home/airflow/.local/lib/python3.7/site-packages/sqlalchemy/pool/impl.py", line 259, in _do_get
    return self._create_connection()
  File "/home/airflow/.local/lib/python3.7/site-packages/sqlalchemy/pool/base.py", line 247, in _create_connection
    return _ConnectionRecord(self)
  File "/home/airflow/.local/lib/python3.7/site-packages/sqlalchemy/pool/base.py", line 362, in __init__
    self.__connect(first_connect_check=True)
  File "/home/airflow/.local/lib/python3.7/site-packages/sqlalchemy/pool/base.py", line 605, in __connect
    pool.logger.debug("Error on connect(): %s", e)
  File "/home/airflow/.local/lib/python3.7/site-packages/sqlalchemy/util/langhelpers.py", line 72, in __exit__
    with_traceback=exc_tb,
  File "/home/airflow/.local/lib/python3.7/site-packages/sqlalchemy/util/compat.py", line 211, in raise_
    raise exception
  File "/home/airflow/.local/lib/python3.7/site-packages/sqlalchemy/pool/base.py", line 599, in __connect
    connection = pool._invoke_creator(self)
  File "/home/airflow/.local/lib/python3.7/site-packages/sqlalchemy/engine/create.py", line 578, in connect
    return dialect.connect(*cargs, **cparams)
  File "/home/airflow/.local/lib/python3.7/site-packages/sqlalchemy/engine/default.py", line 583, in connect
    return self.dbapi.connect(*cargs, **cparams)
  File "/home/airflow/.local/lib/python3.7/site-packages/psycopg2/__init__.py", line 122, in connect
    conn = _connect(dsn, connection_factory=connection_factory, **kwasync)
psycopg2.OperationalError: could not translate host name "postgres_***" to address: Temporary failure in name resolution


The above exception was the direct cause of the following exception:

Traceback (most recent call last):
  File "/home/airflow/.local/lib/python3.7/site-packages/airflow/models/taskinstance.py", line 1453, in _run_raw_task
    self.refresh_from_db(lock_for_update=True, session=session)
  File "/home/airflow/.local/lib/python3.7/site-packages/airflow/utils/session.py", line 68, in wrapper
    return func(*args, **kwargs)
  File "/home/airflow/.local/lib/python3.7/site-packages/airflow/models/taskinstance.py", line 869, in refresh_from_db
    for attempt in run_with_db_retries(logger=self.log):
  File "/home/airflow/.local/lib/python3.7/site-packages/tenacity/__init__.py", line 382, in __iter__
    do = self.iter(retry_state=retry_state)
  File "/home/airflow/.local/lib/python3.7/site-packages/tenacity/__init__.py", line 360, in iter
    raise retry_exc.reraise()
  File "/home/airflow/.local/lib/python3.7/site-packages/tenacity/__init__.py", line 193, in reraise
    raise self.last_attempt.result()
  File "/usr/local/lib/python3.7/concurrent/futures/_base.py", line 428, in result
    return self.__get_result()
  File "/usr/local/lib/python3.7/concurrent/futures/_base.py", line 384, in __get_result
    raise self._exception
  File "/home/airflow/.local/lib/python3.7/site-packages/airflow/models/taskinstance.py", line 871, in refresh_from_db
    ti: Optional[TaskInstance] = qry.with_for_update().first()
  File "/home/airflow/.local/lib/python3.7/site-packages/sqlalchemy/orm/query.py", line 2734, in first
    return self.limit(1)._iter().first()
  File "/home/airflow/.local/lib/python3.7/site-packages/sqlalchemy/orm/query.py", line 2821, in _iter
    execution_options={"_sa_orm_load_options": self.load_options},
  File "/home/airflow/.local/lib/python3.7/site-packages/sqlalchemy/orm/session.py", line 1669, in execute
    conn = self._connection_for_bind(bind, close_with_result=True)
  File "/home/airflow/.local/lib/python3.7/site-packages/sqlalchemy/orm/session.py", line 1520, in _connection_for_bind
    engine, execution_options
  File "/home/airflow/.local/lib/python3.7/site-packages/sqlalchemy/orm/session.py", line 747, in _connection_for_bind
    conn = bind.connect()
  File "/home/airflow/.local/lib/python3.7/site-packages/sqlalchemy/engine/base.py", line 3095, in connect
    return self._connection_cls(self, close_with_result=close_with_result)
  File "/home/airflow/.local/lib/python3.7/site-packages/sqlalchemy/engine/base.py", line 91, in __init__
    else engine.raw_connection()
  File "/home/airflow/.local/lib/python3.7/site-packages/sqlalchemy/engine/base.py", line 3174, in raw_connection
    return self._wrap_pool_connect(self.pool.connect, _connection)
  File "/home/airflow/.local/lib/python3.7/site-packages/sqlalchemy/engine/base.py", line 3145, in _wrap_pool_connect
    e, dialect, self
  File "/home/airflow/.local/lib/python3.7/site-packages/sqlalchemy/engine/base.py", line 2004, in _handle_dbapi_exception_noconnection
    sqlalchemy_exception, with_traceback=exc_info[2], from_=e
  File "/home/airflow/.local/lib/python3.7/site-packages/sqlalchemy/util/compat.py", line 211, in raise_
    raise exception
  File "/home/airflow/.local/lib/python3.7/site-packages/sqlalchemy/engine/base.py", line 3141, in _wrap_pool_connect
    return fn()
  File "/home/airflow/.local/lib/python3.7/site-packages/sqlalchemy/pool/base.py", line 301, in connect
    return _ConnectionFairy._checkout(self)
  File "/home/airflow/.local/lib/python3.7/site-packages/sqlalchemy/pool/base.py", line 755, in _checkout
    fairy = _ConnectionRecord.checkout(pool)
  File "/home/airflow/.local/lib/python3.7/site-packages/sqlalchemy/pool/base.py", line 419, in checkout
    rec = pool._do_get()
  File "/home/airflow/.local/lib/python3.7/site-packages/sqlalchemy/pool/impl.py", line 259, in _do_get
    return self._create_connection()
  File "/home/airflow/.local/lib/python3.7/site-packages/sqlalchemy/pool/base.py", line 247, in _create_connection
    return _ConnectionRecord(self)
  File "/home/airflow/.local/lib/python3.7/site-packages/sqlalchemy/pool/base.py", line 362, in __init__
    self.__connect(first_connect_check=True)
  File "/home/airflow/.local/lib/python3.7/site-packages/sqlalchemy/pool/base.py", line 605, in __connect
    pool.logger.debug("Error on connect(): %s", e)
  File "/home/airflow/.local/lib/python3.7/site-packages/sqlalchemy/util/langhelpers.py", line 72, in __exit__
    with_traceback=exc_tb,
  File "/home/airflow/.local/lib/python3.7/site-packages/sqlalchemy/util/compat.py", line 211, in raise_
    raise exception
  File "/home/airflow/.local/lib/python3.7/site-packages/sqlalchemy/pool/base.py", line 599, in __connect
    connection = pool._invoke_creator(self)
  File "/home/airflow/.local/lib/python3.7/site-packages/sqlalchemy/engine/create.py", line 578, in connect
    return dialect.connect(*cargs, **cparams)
  File "/home/airflow/.local/lib/python3.7/site-packages/sqlalchemy/engine/default.py", line 583, in connect
    return self.dbapi.connect(*cargs, **cparams)
  File "/home/airflow/.local/lib/python3.7/site-packages/psycopg2/__init__.py", line 122, in connect
    conn = _connect(dsn, connection_factory=connection_factory, **kwasync)
sqlalchemy.exc.OperationalError: (psycopg2.OperationalError) could not translate host name "postgres_***" to address: Temporary failure in name resolution

(Background on this error at: http://sqlalche.me/e/14/e3q8)
[2022-06-19 18:00:23,223] {standard_task_runner.py:97} ERROR - Failed to execute job 560 for task price_test_scale-apple-iphone-xs-512gb-space-grau_h_6248 ((psycopg2.OperationalError) could not translate host name "postgres_source" to address: Temporary failure in name resolution

(Background on this error at: http://sqlalche.me/e/14/e3q8); 1333)
[2022-06-19 18:00:23,251] {process_utils.py:75} INFO - Process psutil.Process(pid=1333, status='terminated', exitcode=1, started='17:55:35') (1333) terminated with exit code 1
[2022-06-19 18:00:23,252] {local_task_job.py:156} INFO - Task exited with return code 143
