[2022-06-12 23:12:32,242] {taskinstance.py:1159} INFO - Dependencies all met for <TaskInstance: T-dbt-job-dimensions.dbt_clone_and_transform-dimensions scheduled__2022-06-12T21:09:30.915751+00:00 [queued]>
[2022-06-12 23:12:32,257] {taskinstance.py:1159} INFO - Dependencies all met for <TaskInstance: T-dbt-job-dimensions.dbt_clone_and_transform-dimensions scheduled__2022-06-12T21:09:30.915751+00:00 [queued]>
[2022-06-12 23:12:32,257] {taskinstance.py:1356} INFO - 
--------------------------------------------------------------------------------
[2022-06-12 23:12:32,257] {taskinstance.py:1357} INFO - Starting attempt 1 of 2
[2022-06-12 23:12:32,257] {taskinstance.py:1358} INFO - 
--------------------------------------------------------------------------------
[2022-06-12 23:12:32,276] {taskinstance.py:1377} INFO - Executing <Task(BashOperator): dbt_clone_and_transform-dimensions> on 2022-06-12 21:09:30.915751+00:00
[2022-06-12 23:12:32,282] {standard_task_runner.py:52} INFO - Started process 164 to run task
[2022-06-12 23:12:32,285] {standard_task_runner.py:79} INFO - Running: ['airflow', 'tasks', 'run', 'T-dbt-job-dimensions', 'dbt_clone_and_transform-dimensions', 'scheduled__2022-06-12T21:09:30.915751+00:00', '--job-id', '25', '--raw', '--subdir', 'DAGS_FOLDER/docker_job/dbt_model.py', '--cfg-path', '/tmp/tmpnoenz1fc', '--error-file', '/tmp/tmpz6xoufyu']
[2022-06-12 23:12:32,286] {standard_task_runner.py:80} INFO - Job 25: Subtask dbt_clone_and_transform-dimensions
[2022-06-12 23:12:32,325] {warnings.py:110} WARNING - /home/airflow/.local/lib/python3.7/site-packages/airflow/configuration.py:525: DeprecationWarning: The sql_alchemy_conn option in [core] has been moved to the sql_alchemy_conn option in [database] - the old setting has been used, but please update your config.
  option = self._get_environment_variables(deprecated_key, deprecated_section, key, section)

[2022-06-12 23:12:32,394] {task_command.py:370} INFO - Running <TaskInstance: T-dbt-job-dimensions.dbt_clone_and_transform-dimensions scheduled__2022-06-12T21:09:30.915751+00:00 [running]> on host f269bd168226
[2022-06-12 23:12:32,489] {taskinstance.py:1571} INFO - Exporting the following env vars:
AIRFLOW_CTX_DAG_EMAIL=samuelolle@yahoo.com
AIRFLOW_CTX_DAG_OWNER=airflow
AIRFLOW_CTX_DAG_ID=T-dbt-job-dimensions
AIRFLOW_CTX_TASK_ID=dbt_clone_and_transform-dimensions
AIRFLOW_CTX_EXECUTION_DATE=2022-06-12T21:09:30.915751+00:00
AIRFLOW_CTX_TRY_NUMBER=1
AIRFLOW_CTX_DAG_RUN_ID=scheduled__2022-06-12T21:09:30.915751+00:00
[2022-06-12 23:12:32,490] {subprocess.py:62} INFO - Tmp dir root location: 
 /tmp
[2022-06-12 23:12:32,491] {subprocess.py:74} INFO - Running command: ['bash', '-c', " rm -rf /tmp/dimensions && mkdir /tmp/dimensions                            && cp -r /tmp/dbt /tmp/dimensions/dbt                             && cd /tmp/dimensions/dbt && python3 -m venv venv                             && export PIP_USER=false                             && *** /tmp/dimensions/dbt/venv/bin/activate                             && pip  install --quiet --upgrade pip setuptools                             && pip3 install --quiet 'MarkupSafe<=2.0.1' 'dbt-postgres' 'dbt-core'                             && dbt --version && deactivate                             && cd /tmp/dimensions/dbt && *** /tmp/dimensions/dbt/venv/bin/activate                             && dbt deps --profiles-dir /tmp/dimensions/dbt/ && dbt seed --profiles-dir /tmp/dimensions/dbt/                             && dbt run --models dimensions --profiles-dir /tmp/dimensions/dbt/"]
[2022-06-12 23:12:32,506] {subprocess.py:85} INFO - Output:
[2022-06-12 23:13:00,256] {base_job.py:229} ERROR - LocalTaskJob heartbeat got an exception
Traceback (most recent call last):
  File "/home/airflow/.local/lib/python3.7/site-packages/sqlalchemy/engine/base.py", line 3141, in _wrap_pool_connect
    return fn()
  File "/home/airflow/.local/lib/python3.7/site-packages/sqlalchemy/pool/base.py", line 301, in connect
    return _ConnectionFairy._checkout(self)
  File "/home/airflow/.local/lib/python3.7/site-packages/sqlalchemy/pool/base.py", line 755, in _checkout
    fairy = _ConnectionRecord.checkout(pool)
  File "/home/airflow/.local/lib/python3.7/site-packages/sqlalchemy/pool/base.py", line 419, in checkout
    rec = pool._do_get()
  File "/home/airflow/.local/lib/python3.7/site-packages/sqlalchemy/pool/impl.py", line 259, in _do_get
    return self._create_connection()
  File "/home/airflow/.local/lib/python3.7/site-packages/sqlalchemy/pool/base.py", line 247, in _create_connection
    return _ConnectionRecord(self)
  File "/home/airflow/.local/lib/python3.7/site-packages/sqlalchemy/pool/base.py", line 362, in __init__
    self.__connect(first_connect_check=True)
  File "/home/airflow/.local/lib/python3.7/site-packages/sqlalchemy/pool/base.py", line 605, in __connect
    pool.logger.debug("Error on connect(): %s", e)
  File "/home/airflow/.local/lib/python3.7/site-packages/sqlalchemy/util/langhelpers.py", line 72, in __exit__
    with_traceback=exc_tb,
  File "/home/airflow/.local/lib/python3.7/site-packages/sqlalchemy/util/compat.py", line 211, in raise_
    raise exception
  File "/home/airflow/.local/lib/python3.7/site-packages/sqlalchemy/pool/base.py", line 599, in __connect
    connection = pool._invoke_creator(self)
  File "/home/airflow/.local/lib/python3.7/site-packages/sqlalchemy/engine/create.py", line 578, in connect
    return dialect.connect(*cargs, **cparams)
  File "/home/airflow/.local/lib/python3.7/site-packages/sqlalchemy/engine/default.py", line 583, in connect
    return self.dbapi.connect(*cargs, **cparams)
  File "/home/airflow/.local/lib/python3.7/site-packages/psycopg2/__init__.py", line 122, in connect
    conn = _connect(dsn, connection_factory=connection_factory, **kwasync)
psycopg2.OperationalError: could not translate host name "postgres_***" to address: Temporary failure in name resolution


The above exception was the direct cause of the following exception:

Traceback (most recent call last):
  File "/home/airflow/.local/lib/python3.7/site-packages/airflow/jobs/base_job.py", line 201, in heartbeat
    session.merge(self)
  File "/home/airflow/.local/lib/python3.7/site-packages/sqlalchemy/orm/session.py", line 2877, in merge
    _resolve_conflict_map=_resolve_conflict_map,
  File "/home/airflow/.local/lib/python3.7/site-packages/sqlalchemy/orm/session.py", line 2950, in _merge
    merged = self.get(mapper.class_, key[1], identity_token=key[2])
  File "/home/airflow/.local/lib/python3.7/site-packages/sqlalchemy/orm/session.py", line 2702, in get
    identity_token=identity_token,
  File "/home/airflow/.local/lib/python3.7/site-packages/sqlalchemy/orm/session.py", line 2800, in _get_impl
    load_options=load_options,
  File "/home/airflow/.local/lib/python3.7/site-packages/sqlalchemy/orm/loading.py", line 535, in load_on_pk_identity
    bind_arguments=bind_arguments,
  File "/home/airflow/.local/lib/python3.7/site-packages/sqlalchemy/orm/session.py", line 1669, in execute
    conn = self._connection_for_bind(bind, close_with_result=True)
  File "/home/airflow/.local/lib/python3.7/site-packages/sqlalchemy/orm/session.py", line 1520, in _connection_for_bind
    engine, execution_options
  File "/home/airflow/.local/lib/python3.7/site-packages/sqlalchemy/orm/session.py", line 747, in _connection_for_bind
    conn = bind.connect()
  File "/home/airflow/.local/lib/python3.7/site-packages/sqlalchemy/engine/base.py", line 3095, in connect
    return self._connection_cls(self, close_with_result=close_with_result)
  File "/home/airflow/.local/lib/python3.7/site-packages/sqlalchemy/engine/base.py", line 91, in __init__
    else engine.raw_connection()
  File "/home/airflow/.local/lib/python3.7/site-packages/sqlalchemy/engine/base.py", line 3174, in raw_connection
    return self._wrap_pool_connect(self.pool.connect, _connection)
  File "/home/airflow/.local/lib/python3.7/site-packages/sqlalchemy/engine/base.py", line 3145, in _wrap_pool_connect
    e, dialect, self
  File "/home/airflow/.local/lib/python3.7/site-packages/sqlalchemy/engine/base.py", line 2004, in _handle_dbapi_exception_noconnection
    sqlalchemy_exception, with_traceback=exc_info[2], from_=e
  File "/home/airflow/.local/lib/python3.7/site-packages/sqlalchemy/util/compat.py", line 211, in raise_
    raise exception
  File "/home/airflow/.local/lib/python3.7/site-packages/sqlalchemy/engine/base.py", line 3141, in _wrap_pool_connect
    return fn()
  File "/home/airflow/.local/lib/python3.7/site-packages/sqlalchemy/pool/base.py", line 301, in connect
    return _ConnectionFairy._checkout(self)
  File "/home/airflow/.local/lib/python3.7/site-packages/sqlalchemy/pool/base.py", line 755, in _checkout
    fairy = _ConnectionRecord.checkout(pool)
  File "/home/airflow/.local/lib/python3.7/site-packages/sqlalchemy/pool/base.py", line 419, in checkout
    rec = pool._do_get()
  File "/home/airflow/.local/lib/python3.7/site-packages/sqlalchemy/pool/impl.py", line 259, in _do_get
    return self._create_connection()
  File "/home/airflow/.local/lib/python3.7/site-packages/sqlalchemy/pool/base.py", line 247, in _create_connection
    return _ConnectionRecord(self)
  File "/home/airflow/.local/lib/python3.7/site-packages/sqlalchemy/pool/base.py", line 362, in __init__
    self.__connect(first_connect_check=True)
  File "/home/airflow/.local/lib/python3.7/site-packages/sqlalchemy/pool/base.py", line 605, in __connect
    pool.logger.debug("Error on connect(): %s", e)
  File "/home/airflow/.local/lib/python3.7/site-packages/sqlalchemy/util/langhelpers.py", line 72, in __exit__
    with_traceback=exc_tb,
  File "/home/airflow/.local/lib/python3.7/site-packages/sqlalchemy/util/compat.py", line 211, in raise_
    raise exception
  File "/home/airflow/.local/lib/python3.7/site-packages/sqlalchemy/pool/base.py", line 599, in __connect
    connection = pool._invoke_creator(self)
  File "/home/airflow/.local/lib/python3.7/site-packages/sqlalchemy/engine/create.py", line 578, in connect
    return dialect.connect(*cargs, **cparams)
  File "/home/airflow/.local/lib/python3.7/site-packages/sqlalchemy/engine/default.py", line 583, in connect
    return self.dbapi.connect(*cargs, **cparams)
  File "/home/airflow/.local/lib/python3.7/site-packages/psycopg2/__init__.py", line 122, in connect
    conn = _connect(dsn, connection_factory=connection_factory, **kwasync)
sqlalchemy.exc.OperationalError: (psycopg2.OperationalError) could not translate host name "postgres_***" to address: Temporary failure in name resolution

(Background on this error at: http://sqlalche.me/e/14/e3q8)
[2022-06-12 23:14:42,553] {base_job.py:229} ERROR - LocalTaskJob heartbeat got an exception
Traceback (most recent call last):
  File "/home/airflow/.local/lib/python3.7/site-packages/sqlalchemy/engine/base.py", line 3141, in _wrap_pool_connect
    return fn()
  File "/home/airflow/.local/lib/python3.7/site-packages/sqlalchemy/pool/base.py", line 301, in connect
    return _ConnectionFairy._checkout(self)
  File "/home/airflow/.local/lib/python3.7/site-packages/sqlalchemy/pool/base.py", line 755, in _checkout
    fairy = _ConnectionRecord.checkout(pool)
  File "/home/airflow/.local/lib/python3.7/site-packages/sqlalchemy/pool/base.py", line 419, in checkout
    rec = pool._do_get()
  File "/home/airflow/.local/lib/python3.7/site-packages/sqlalchemy/pool/impl.py", line 259, in _do_get
    return self._create_connection()
  File "/home/airflow/.local/lib/python3.7/site-packages/sqlalchemy/pool/base.py", line 247, in _create_connection
    return _ConnectionRecord(self)
  File "/home/airflow/.local/lib/python3.7/site-packages/sqlalchemy/pool/base.py", line 362, in __init__
    self.__connect(first_connect_check=True)
  File "/home/airflow/.local/lib/python3.7/site-packages/sqlalchemy/pool/base.py", line 605, in __connect
    pool.logger.debug("Error on connect(): %s", e)
  File "/home/airflow/.local/lib/python3.7/site-packages/sqlalchemy/util/langhelpers.py", line 72, in __exit__
    with_traceback=exc_tb,
  File "/home/airflow/.local/lib/python3.7/site-packages/sqlalchemy/util/compat.py", line 211, in raise_
    raise exception
  File "/home/airflow/.local/lib/python3.7/site-packages/sqlalchemy/pool/base.py", line 599, in __connect
    connection = pool._invoke_creator(self)
  File "/home/airflow/.local/lib/python3.7/site-packages/sqlalchemy/engine/create.py", line 578, in connect
    return dialect.connect(*cargs, **cparams)
  File "/home/airflow/.local/lib/python3.7/site-packages/sqlalchemy/engine/default.py", line 583, in connect
    return self.dbapi.connect(*cargs, **cparams)
  File "/home/airflow/.local/lib/python3.7/site-packages/psycopg2/__init__.py", line 122, in connect
    conn = _connect(dsn, connection_factory=connection_factory, **kwasync)
psycopg2.OperationalError: could not translate host name "postgres_***" to address: Temporary failure in name resolution


The above exception was the direct cause of the following exception:

Traceback (most recent call last):
  File "/home/airflow/.local/lib/python3.7/site-packages/airflow/jobs/base_job.py", line 201, in heartbeat
    session.merge(self)
  File "/home/airflow/.local/lib/python3.7/site-packages/sqlalchemy/orm/session.py", line 2877, in merge
    _resolve_conflict_map=_resolve_conflict_map,
  File "/home/airflow/.local/lib/python3.7/site-packages/sqlalchemy/orm/session.py", line 2950, in _merge
    merged = self.get(mapper.class_, key[1], identity_token=key[2])
  File "/home/airflow/.local/lib/python3.7/site-packages/sqlalchemy/orm/session.py", line 2702, in get
    identity_token=identity_token,
  File "/home/airflow/.local/lib/python3.7/site-packages/sqlalchemy/orm/session.py", line 2800, in _get_impl
    load_options=load_options,
  File "/home/airflow/.local/lib/python3.7/site-packages/sqlalchemy/orm/loading.py", line 535, in load_on_pk_identity
    bind_arguments=bind_arguments,
  File "/home/airflow/.local/lib/python3.7/site-packages/sqlalchemy/orm/session.py", line 1669, in execute
    conn = self._connection_for_bind(bind, close_with_result=True)
  File "/home/airflow/.local/lib/python3.7/site-packages/sqlalchemy/orm/session.py", line 1520, in _connection_for_bind
    engine, execution_options
  File "/home/airflow/.local/lib/python3.7/site-packages/sqlalchemy/orm/session.py", line 747, in _connection_for_bind
    conn = bind.connect()
  File "/home/airflow/.local/lib/python3.7/site-packages/sqlalchemy/engine/base.py", line 3095, in connect
    return self._connection_cls(self, close_with_result=close_with_result)
  File "/home/airflow/.local/lib/python3.7/site-packages/sqlalchemy/engine/base.py", line 91, in __init__
    else engine.raw_connection()
  File "/home/airflow/.local/lib/python3.7/site-packages/sqlalchemy/engine/base.py", line 3174, in raw_connection
    return self._wrap_pool_connect(self.pool.connect, _connection)
  File "/home/airflow/.local/lib/python3.7/site-packages/sqlalchemy/engine/base.py", line 3145, in _wrap_pool_connect
    e, dialect, self
  File "/home/airflow/.local/lib/python3.7/site-packages/sqlalchemy/engine/base.py", line 2004, in _handle_dbapi_exception_noconnection
    sqlalchemy_exception, with_traceback=exc_info[2], from_=e
  File "/home/airflow/.local/lib/python3.7/site-packages/sqlalchemy/util/compat.py", line 211, in raise_
    raise exception
  File "/home/airflow/.local/lib/python3.7/site-packages/sqlalchemy/engine/base.py", line 3141, in _wrap_pool_connect
    return fn()
  File "/home/airflow/.local/lib/python3.7/site-packages/sqlalchemy/pool/base.py", line 301, in connect
    return _ConnectionFairy._checkout(self)
  File "/home/airflow/.local/lib/python3.7/site-packages/sqlalchemy/pool/base.py", line 755, in _checkout
    fairy = _ConnectionRecord.checkout(pool)
  File "/home/airflow/.local/lib/python3.7/site-packages/sqlalchemy/pool/base.py", line 419, in checkout
    rec = pool._do_get()
  File "/home/airflow/.local/lib/python3.7/site-packages/sqlalchemy/pool/impl.py", line 259, in _do_get
    return self._create_connection()
  File "/home/airflow/.local/lib/python3.7/site-packages/sqlalchemy/pool/base.py", line 247, in _create_connection
    return _ConnectionRecord(self)
  File "/home/airflow/.local/lib/python3.7/site-packages/sqlalchemy/pool/base.py", line 362, in __init__
    self.__connect(first_connect_check=True)
  File "/home/airflow/.local/lib/python3.7/site-packages/sqlalchemy/pool/base.py", line 605, in __connect
    pool.logger.debug("Error on connect(): %s", e)
  File "/home/airflow/.local/lib/python3.7/site-packages/sqlalchemy/util/langhelpers.py", line 72, in __exit__
    with_traceback=exc_tb,
  File "/home/airflow/.local/lib/python3.7/site-packages/sqlalchemy/util/compat.py", line 211, in raise_
    raise exception
  File "/home/airflow/.local/lib/python3.7/site-packages/sqlalchemy/pool/base.py", line 599, in __connect
    connection = pool._invoke_creator(self)
  File "/home/airflow/.local/lib/python3.7/site-packages/sqlalchemy/engine/create.py", line 578, in connect
    return dialect.connect(*cargs, **cparams)
  File "/home/airflow/.local/lib/python3.7/site-packages/sqlalchemy/engine/default.py", line 583, in connect
    return self.dbapi.connect(*cargs, **cparams)
  File "/home/airflow/.local/lib/python3.7/site-packages/psycopg2/__init__.py", line 122, in connect
    conn = _connect(dsn, connection_factory=connection_factory, **kwasync)
sqlalchemy.exc.OperationalError: (psycopg2.OperationalError) could not translate host name "postgres_***" to address: Temporary failure in name resolution

(Background on this error at: http://sqlalche.me/e/14/e3q8)
[2022-06-12 23:15:56,078] {base_job.py:229} ERROR - LocalTaskJob heartbeat got an exception
Traceback (most recent call last):
  File "/home/airflow/.local/lib/python3.7/site-packages/sqlalchemy/engine/base.py", line 3141, in _wrap_pool_connect
    return fn()
  File "/home/airflow/.local/lib/python3.7/site-packages/sqlalchemy/pool/base.py", line 301, in connect
    return _ConnectionFairy._checkout(self)
  File "/home/airflow/.local/lib/python3.7/site-packages/sqlalchemy/pool/base.py", line 755, in _checkout
    fairy = _ConnectionRecord.checkout(pool)
  File "/home/airflow/.local/lib/python3.7/site-packages/sqlalchemy/pool/base.py", line 419, in checkout
    rec = pool._do_get()
  File "/home/airflow/.local/lib/python3.7/site-packages/sqlalchemy/pool/impl.py", line 259, in _do_get
    return self._create_connection()
  File "/home/airflow/.local/lib/python3.7/site-packages/sqlalchemy/pool/base.py", line 247, in _create_connection
    return _ConnectionRecord(self)
  File "/home/airflow/.local/lib/python3.7/site-packages/sqlalchemy/pool/base.py", line 362, in __init__
    self.__connect(first_connect_check=True)
  File "/home/airflow/.local/lib/python3.7/site-packages/sqlalchemy/pool/base.py", line 605, in __connect
    pool.logger.debug("Error on connect(): %s", e)
  File "/home/airflow/.local/lib/python3.7/site-packages/sqlalchemy/util/langhelpers.py", line 72, in __exit__
    with_traceback=exc_tb,
  File "/home/airflow/.local/lib/python3.7/site-packages/sqlalchemy/util/compat.py", line 211, in raise_
    raise exception
  File "/home/airflow/.local/lib/python3.7/site-packages/sqlalchemy/pool/base.py", line 599, in __connect
    connection = pool._invoke_creator(self)
  File "/home/airflow/.local/lib/python3.7/site-packages/sqlalchemy/engine/create.py", line 578, in connect
    return dialect.connect(*cargs, **cparams)
  File "/home/airflow/.local/lib/python3.7/site-packages/sqlalchemy/engine/default.py", line 583, in connect
    return self.dbapi.connect(*cargs, **cparams)
  File "/home/airflow/.local/lib/python3.7/site-packages/psycopg2/__init__.py", line 122, in connect
    conn = _connect(dsn, connection_factory=connection_factory, **kwasync)
psycopg2.OperationalError: could not translate host name "postgres_***" to address: Temporary failure in name resolution


The above exception was the direct cause of the following exception:

Traceback (most recent call last):
  File "/home/airflow/.local/lib/python3.7/site-packages/airflow/jobs/base_job.py", line 201, in heartbeat
    session.merge(self)
  File "/home/airflow/.local/lib/python3.7/site-packages/sqlalchemy/orm/session.py", line 2877, in merge
    _resolve_conflict_map=_resolve_conflict_map,
  File "/home/airflow/.local/lib/python3.7/site-packages/sqlalchemy/orm/session.py", line 2950, in _merge
    merged = self.get(mapper.class_, key[1], identity_token=key[2])
  File "/home/airflow/.local/lib/python3.7/site-packages/sqlalchemy/orm/session.py", line 2702, in get
    identity_token=identity_token,
  File "/home/airflow/.local/lib/python3.7/site-packages/sqlalchemy/orm/session.py", line 2800, in _get_impl
    load_options=load_options,
  File "/home/airflow/.local/lib/python3.7/site-packages/sqlalchemy/orm/loading.py", line 535, in load_on_pk_identity
    bind_arguments=bind_arguments,
  File "/home/airflow/.local/lib/python3.7/site-packages/sqlalchemy/orm/session.py", line 1669, in execute
    conn = self._connection_for_bind(bind, close_with_result=True)
  File "/home/airflow/.local/lib/python3.7/site-packages/sqlalchemy/orm/session.py", line 1520, in _connection_for_bind
    engine, execution_options
  File "/home/airflow/.local/lib/python3.7/site-packages/sqlalchemy/orm/session.py", line 747, in _connection_for_bind
    conn = bind.connect()
  File "/home/airflow/.local/lib/python3.7/site-packages/sqlalchemy/engine/base.py", line 3095, in connect
    return self._connection_cls(self, close_with_result=close_with_result)
  File "/home/airflow/.local/lib/python3.7/site-packages/sqlalchemy/engine/base.py", line 91, in __init__
    else engine.raw_connection()
  File "/home/airflow/.local/lib/python3.7/site-packages/sqlalchemy/engine/base.py", line 3174, in raw_connection
    return self._wrap_pool_connect(self.pool.connect, _connection)
  File "/home/airflow/.local/lib/python3.7/site-packages/sqlalchemy/engine/base.py", line 3145, in _wrap_pool_connect
    e, dialect, self
  File "/home/airflow/.local/lib/python3.7/site-packages/sqlalchemy/engine/base.py", line 2004, in _handle_dbapi_exception_noconnection
    sqlalchemy_exception, with_traceback=exc_info[2], from_=e
  File "/home/airflow/.local/lib/python3.7/site-packages/sqlalchemy/util/compat.py", line 211, in raise_
    raise exception
  File "/home/airflow/.local/lib/python3.7/site-packages/sqlalchemy/engine/base.py", line 3141, in _wrap_pool_connect
    return fn()
  File "/home/airflow/.local/lib/python3.7/site-packages/sqlalchemy/pool/base.py", line 301, in connect
    return _ConnectionFairy._checkout(self)
  File "/home/airflow/.local/lib/python3.7/site-packages/sqlalchemy/pool/base.py", line 755, in _checkout
    fairy = _ConnectionRecord.checkout(pool)
  File "/home/airflow/.local/lib/python3.7/site-packages/sqlalchemy/pool/base.py", line 419, in checkout
    rec = pool._do_get()
  File "/home/airflow/.local/lib/python3.7/site-packages/sqlalchemy/pool/impl.py", line 259, in _do_get
    return self._create_connection()
  File "/home/airflow/.local/lib/python3.7/site-packages/sqlalchemy/pool/base.py", line 247, in _create_connection
    return _ConnectionRecord(self)
  File "/home/airflow/.local/lib/python3.7/site-packages/sqlalchemy/pool/base.py", line 362, in __init__
    self.__connect(first_connect_check=True)
  File "/home/airflow/.local/lib/python3.7/site-packages/sqlalchemy/pool/base.py", line 605, in __connect
    pool.logger.debug("Error on connect(): %s", e)
  File "/home/airflow/.local/lib/python3.7/site-packages/sqlalchemy/util/langhelpers.py", line 72, in __exit__
    with_traceback=exc_tb,
  File "/home/airflow/.local/lib/python3.7/site-packages/sqlalchemy/util/compat.py", line 211, in raise_
    raise exception
  File "/home/airflow/.local/lib/python3.7/site-packages/sqlalchemy/pool/base.py", line 599, in __connect
    connection = pool._invoke_creator(self)
  File "/home/airflow/.local/lib/python3.7/site-packages/sqlalchemy/engine/create.py", line 578, in connect
    return dialect.connect(*cargs, **cparams)
  File "/home/airflow/.local/lib/python3.7/site-packages/sqlalchemy/engine/default.py", line 583, in connect
    return self.dbapi.connect(*cargs, **cparams)
  File "/home/airflow/.local/lib/python3.7/site-packages/psycopg2/__init__.py", line 122, in connect
    conn = _connect(dsn, connection_factory=connection_factory, **kwasync)
sqlalchemy.exc.OperationalError: (psycopg2.OperationalError) could not translate host name "postgres_***" to address: Temporary failure in name resolution

(Background on this error at: http://sqlalche.me/e/14/e3q8)
[2022-06-12 23:16:05,708] {subprocess.py:92} INFO - Core:
[2022-06-12 23:16:05,709] {subprocess.py:92} INFO -   - installed: 1.1.0
[2022-06-12 23:16:05,709] {subprocess.py:92} INFO -   - latest:    1.1.0 - [32mUp to date![0m
[2022-06-12 23:16:05,709] {subprocess.py:92} INFO - 
[2022-06-12 23:16:05,709] {subprocess.py:92} INFO - Plugins:
[2022-06-12 23:16:05,709] {subprocess.py:92} INFO -   - postgres: 1.1.0 - [32mUp to date![0m
[2022-06-12 23:16:09,304] {subprocess.py:92} INFO - [0m23:16:09  Running with dbt=1.1.0
[2022-06-12 23:16:09,306] {subprocess.py:92} INFO - [0m23:16:09  Warning: No packages were found in packages.yml
[2022-06-12 23:16:32,460] {base_job.py:229} ERROR - LocalTaskJob heartbeat got an exception
Traceback (most recent call last):
  File "/home/airflow/.local/lib/python3.7/site-packages/sqlalchemy/engine/base.py", line 3141, in _wrap_pool_connect
    return fn()
  File "/home/airflow/.local/lib/python3.7/site-packages/sqlalchemy/pool/base.py", line 301, in connect
    return _ConnectionFairy._checkout(self)
  File "/home/airflow/.local/lib/python3.7/site-packages/sqlalchemy/pool/base.py", line 755, in _checkout
    fairy = _ConnectionRecord.checkout(pool)
  File "/home/airflow/.local/lib/python3.7/site-packages/sqlalchemy/pool/base.py", line 419, in checkout
    rec = pool._do_get()
  File "/home/airflow/.local/lib/python3.7/site-packages/sqlalchemy/pool/impl.py", line 259, in _do_get
    return self._create_connection()
  File "/home/airflow/.local/lib/python3.7/site-packages/sqlalchemy/pool/base.py", line 247, in _create_connection
    return _ConnectionRecord(self)
  File "/home/airflow/.local/lib/python3.7/site-packages/sqlalchemy/pool/base.py", line 362, in __init__
    self.__connect(first_connect_check=True)
  File "/home/airflow/.local/lib/python3.7/site-packages/sqlalchemy/pool/base.py", line 605, in __connect
    pool.logger.debug("Error on connect(): %s", e)
  File "/home/airflow/.local/lib/python3.7/site-packages/sqlalchemy/util/langhelpers.py", line 72, in __exit__
    with_traceback=exc_tb,
  File "/home/airflow/.local/lib/python3.7/site-packages/sqlalchemy/util/compat.py", line 211, in raise_
    raise exception
  File "/home/airflow/.local/lib/python3.7/site-packages/sqlalchemy/pool/base.py", line 599, in __connect
    connection = pool._invoke_creator(self)
  File "/home/airflow/.local/lib/python3.7/site-packages/sqlalchemy/engine/create.py", line 578, in connect
    return dialect.connect(*cargs, **cparams)
  File "/home/airflow/.local/lib/python3.7/site-packages/sqlalchemy/engine/default.py", line 583, in connect
    return self.dbapi.connect(*cargs, **cparams)
  File "/home/airflow/.local/lib/python3.7/site-packages/psycopg2/__init__.py", line 122, in connect
    conn = _connect(dsn, connection_factory=connection_factory, **kwasync)
psycopg2.OperationalError: could not translate host name "postgres_***" to address: Temporary failure in name resolution


The above exception was the direct cause of the following exception:

Traceback (most recent call last):
  File "/home/airflow/.local/lib/python3.7/site-packages/airflow/jobs/base_job.py", line 201, in heartbeat
    session.merge(self)
  File "/home/airflow/.local/lib/python3.7/site-packages/sqlalchemy/orm/session.py", line 2877, in merge
    _resolve_conflict_map=_resolve_conflict_map,
  File "/home/airflow/.local/lib/python3.7/site-packages/sqlalchemy/orm/session.py", line 2950, in _merge
    merged = self.get(mapper.class_, key[1], identity_token=key[2])
  File "/home/airflow/.local/lib/python3.7/site-packages/sqlalchemy/orm/session.py", line 2702, in get
    identity_token=identity_token,
  File "/home/airflow/.local/lib/python3.7/site-packages/sqlalchemy/orm/session.py", line 2800, in _get_impl
    load_options=load_options,
  File "/home/airflow/.local/lib/python3.7/site-packages/sqlalchemy/orm/loading.py", line 535, in load_on_pk_identity
    bind_arguments=bind_arguments,
  File "/home/airflow/.local/lib/python3.7/site-packages/sqlalchemy/orm/session.py", line 1669, in execute
    conn = self._connection_for_bind(bind, close_with_result=True)
  File "/home/airflow/.local/lib/python3.7/site-packages/sqlalchemy/orm/session.py", line 1520, in _connection_for_bind
    engine, execution_options
  File "/home/airflow/.local/lib/python3.7/site-packages/sqlalchemy/orm/session.py", line 747, in _connection_for_bind
    conn = bind.connect()
  File "/home/airflow/.local/lib/python3.7/site-packages/sqlalchemy/engine/base.py", line 3095, in connect
    return self._connection_cls(self, close_with_result=close_with_result)
  File "/home/airflow/.local/lib/python3.7/site-packages/sqlalchemy/engine/base.py", line 91, in __init__
    else engine.raw_connection()
  File "/home/airflow/.local/lib/python3.7/site-packages/sqlalchemy/engine/base.py", line 3174, in raw_connection
    return self._wrap_pool_connect(self.pool.connect, _connection)
  File "/home/airflow/.local/lib/python3.7/site-packages/sqlalchemy/engine/base.py", line 3145, in _wrap_pool_connect
    e, dialect, self
  File "/home/airflow/.local/lib/python3.7/site-packages/sqlalchemy/engine/base.py", line 2004, in _handle_dbapi_exception_noconnection
    sqlalchemy_exception, with_traceback=exc_info[2], from_=e
  File "/home/airflow/.local/lib/python3.7/site-packages/sqlalchemy/util/compat.py", line 211, in raise_
    raise exception
  File "/home/airflow/.local/lib/python3.7/site-packages/sqlalchemy/engine/base.py", line 3141, in _wrap_pool_connect
    return fn()
  File "/home/airflow/.local/lib/python3.7/site-packages/sqlalchemy/pool/base.py", line 301, in connect
    return _ConnectionFairy._checkout(self)
  File "/home/airflow/.local/lib/python3.7/site-packages/sqlalchemy/pool/base.py", line 755, in _checkout
    fairy = _ConnectionRecord.checkout(pool)
  File "/home/airflow/.local/lib/python3.7/site-packages/sqlalchemy/pool/base.py", line 419, in checkout
    rec = pool._do_get()
  File "/home/airflow/.local/lib/python3.7/site-packages/sqlalchemy/pool/impl.py", line 259, in _do_get
    return self._create_connection()
  File "/home/airflow/.local/lib/python3.7/site-packages/sqlalchemy/pool/base.py", line 247, in _create_connection
    return _ConnectionRecord(self)
  File "/home/airflow/.local/lib/python3.7/site-packages/sqlalchemy/pool/base.py", line 362, in __init__
    self.__connect(first_connect_check=True)
  File "/home/airflow/.local/lib/python3.7/site-packages/sqlalchemy/pool/base.py", line 605, in __connect
    pool.logger.debug("Error on connect(): %s", e)
  File "/home/airflow/.local/lib/python3.7/site-packages/sqlalchemy/util/langhelpers.py", line 72, in __exit__
    with_traceback=exc_tb,
  File "/home/airflow/.local/lib/python3.7/site-packages/sqlalchemy/util/compat.py", line 211, in raise_
    raise exception
  File "/home/airflow/.local/lib/python3.7/site-packages/sqlalchemy/pool/base.py", line 599, in __connect
    connection = pool._invoke_creator(self)
  File "/home/airflow/.local/lib/python3.7/site-packages/sqlalchemy/engine/create.py", line 578, in connect
    return dialect.connect(*cargs, **cparams)
  File "/home/airflow/.local/lib/python3.7/site-packages/sqlalchemy/engine/default.py", line 583, in connect
    return self.dbapi.connect(*cargs, **cparams)
  File "/home/airflow/.local/lib/python3.7/site-packages/psycopg2/__init__.py", line 122, in connect
    conn = _connect(dsn, connection_factory=connection_factory, **kwasync)
sqlalchemy.exc.OperationalError: (psycopg2.OperationalError) could not translate host name "postgres_***" to address: Temporary failure in name resolution

(Background on this error at: http://sqlalche.me/e/14/e3q8)
[2022-06-12 23:17:18,453] {base_job.py:229} ERROR - LocalTaskJob heartbeat got an exception
Traceback (most recent call last):
  File "/home/airflow/.local/lib/python3.7/site-packages/sqlalchemy/engine/base.py", line 3141, in _wrap_pool_connect
    return fn()
  File "/home/airflow/.local/lib/python3.7/site-packages/sqlalchemy/pool/base.py", line 301, in connect
    return _ConnectionFairy._checkout(self)
  File "/home/airflow/.local/lib/python3.7/site-packages/sqlalchemy/pool/base.py", line 755, in _checkout
    fairy = _ConnectionRecord.checkout(pool)
  File "/home/airflow/.local/lib/python3.7/site-packages/sqlalchemy/pool/base.py", line 419, in checkout
    rec = pool._do_get()
  File "/home/airflow/.local/lib/python3.7/site-packages/sqlalchemy/pool/impl.py", line 259, in _do_get
    return self._create_connection()
  File "/home/airflow/.local/lib/python3.7/site-packages/sqlalchemy/pool/base.py", line 247, in _create_connection
    return _ConnectionRecord(self)
  File "/home/airflow/.local/lib/python3.7/site-packages/sqlalchemy/pool/base.py", line 362, in __init__
    self.__connect(first_connect_check=True)
  File "/home/airflow/.local/lib/python3.7/site-packages/sqlalchemy/pool/base.py", line 605, in __connect
    pool.logger.debug("Error on connect(): %s", e)
  File "/home/airflow/.local/lib/python3.7/site-packages/sqlalchemy/util/langhelpers.py", line 72, in __exit__
    with_traceback=exc_tb,
  File "/home/airflow/.local/lib/python3.7/site-packages/sqlalchemy/util/compat.py", line 211, in raise_
    raise exception
  File "/home/airflow/.local/lib/python3.7/site-packages/sqlalchemy/pool/base.py", line 599, in __connect
    connection = pool._invoke_creator(self)
  File "/home/airflow/.local/lib/python3.7/site-packages/sqlalchemy/engine/create.py", line 578, in connect
    return dialect.connect(*cargs, **cparams)
  File "/home/airflow/.local/lib/python3.7/site-packages/sqlalchemy/engine/default.py", line 583, in connect
    return self.dbapi.connect(*cargs, **cparams)
  File "/home/airflow/.local/lib/python3.7/site-packages/psycopg2/__init__.py", line 122, in connect
    conn = _connect(dsn, connection_factory=connection_factory, **kwasync)
psycopg2.OperationalError: could not translate host name "postgres_***" to address: Temporary failure in name resolution


The above exception was the direct cause of the following exception:

Traceback (most recent call last):
  File "/home/airflow/.local/lib/python3.7/site-packages/airflow/jobs/base_job.py", line 201, in heartbeat
    session.merge(self)
  File "/home/airflow/.local/lib/python3.7/site-packages/sqlalchemy/orm/session.py", line 2877, in merge
    _resolve_conflict_map=_resolve_conflict_map,
  File "/home/airflow/.local/lib/python3.7/site-packages/sqlalchemy/orm/session.py", line 2950, in _merge
    merged = self.get(mapper.class_, key[1], identity_token=key[2])
  File "/home/airflow/.local/lib/python3.7/site-packages/sqlalchemy/orm/session.py", line 2702, in get
    identity_token=identity_token,
  File "/home/airflow/.local/lib/python3.7/site-packages/sqlalchemy/orm/session.py", line 2800, in _get_impl
    load_options=load_options,
  File "/home/airflow/.local/lib/python3.7/site-packages/sqlalchemy/orm/loading.py", line 535, in load_on_pk_identity
    bind_arguments=bind_arguments,
  File "/home/airflow/.local/lib/python3.7/site-packages/sqlalchemy/orm/session.py", line 1669, in execute
    conn = self._connection_for_bind(bind, close_with_result=True)
  File "/home/airflow/.local/lib/python3.7/site-packages/sqlalchemy/orm/session.py", line 1520, in _connection_for_bind
    engine, execution_options
  File "/home/airflow/.local/lib/python3.7/site-packages/sqlalchemy/orm/session.py", line 747, in _connection_for_bind
    conn = bind.connect()
  File "/home/airflow/.local/lib/python3.7/site-packages/sqlalchemy/engine/base.py", line 3095, in connect
    return self._connection_cls(self, close_with_result=close_with_result)
  File "/home/airflow/.local/lib/python3.7/site-packages/sqlalchemy/engine/base.py", line 91, in __init__
    else engine.raw_connection()
  File "/home/airflow/.local/lib/python3.7/site-packages/sqlalchemy/engine/base.py", line 3174, in raw_connection
    return self._wrap_pool_connect(self.pool.connect, _connection)
  File "/home/airflow/.local/lib/python3.7/site-packages/sqlalchemy/engine/base.py", line 3145, in _wrap_pool_connect
    e, dialect, self
  File "/home/airflow/.local/lib/python3.7/site-packages/sqlalchemy/engine/base.py", line 2004, in _handle_dbapi_exception_noconnection
    sqlalchemy_exception, with_traceback=exc_info[2], from_=e
  File "/home/airflow/.local/lib/python3.7/site-packages/sqlalchemy/util/compat.py", line 211, in raise_
    raise exception
  File "/home/airflow/.local/lib/python3.7/site-packages/sqlalchemy/engine/base.py", line 3141, in _wrap_pool_connect
    return fn()
  File "/home/airflow/.local/lib/python3.7/site-packages/sqlalchemy/pool/base.py", line 301, in connect
    return _ConnectionFairy._checkout(self)
  File "/home/airflow/.local/lib/python3.7/site-packages/sqlalchemy/pool/base.py", line 755, in _checkout
    fairy = _ConnectionRecord.checkout(pool)
  File "/home/airflow/.local/lib/python3.7/site-packages/sqlalchemy/pool/base.py", line 419, in checkout
    rec = pool._do_get()
  File "/home/airflow/.local/lib/python3.7/site-packages/sqlalchemy/pool/impl.py", line 259, in _do_get
    return self._create_connection()
  File "/home/airflow/.local/lib/python3.7/site-packages/sqlalchemy/pool/base.py", line 247, in _create_connection
    return _ConnectionRecord(self)
  File "/home/airflow/.local/lib/python3.7/site-packages/sqlalchemy/pool/base.py", line 362, in __init__
    self.__connect(first_connect_check=True)
  File "/home/airflow/.local/lib/python3.7/site-packages/sqlalchemy/pool/base.py", line 605, in __connect
    pool.logger.debug("Error on connect(): %s", e)
  File "/home/airflow/.local/lib/python3.7/site-packages/sqlalchemy/util/langhelpers.py", line 72, in __exit__
    with_traceback=exc_tb,
  File "/home/airflow/.local/lib/python3.7/site-packages/sqlalchemy/util/compat.py", line 211, in raise_
    raise exception
  File "/home/airflow/.local/lib/python3.7/site-packages/sqlalchemy/pool/base.py", line 599, in __connect
    connection = pool._invoke_creator(self)
  File "/home/airflow/.local/lib/python3.7/site-packages/sqlalchemy/engine/create.py", line 578, in connect
    return dialect.connect(*cargs, **cparams)
  File "/home/airflow/.local/lib/python3.7/site-packages/sqlalchemy/engine/default.py", line 583, in connect
    return self.dbapi.connect(*cargs, **cparams)
  File "/home/airflow/.local/lib/python3.7/site-packages/psycopg2/__init__.py", line 122, in connect
    conn = _connect(dsn, connection_factory=connection_factory, **kwasync)
sqlalchemy.exc.OperationalError: (psycopg2.OperationalError) could not translate host name "postgres_***" to address: Temporary failure in name resolution

(Background on this error at: http://sqlalche.me/e/14/e3q8)
[2022-06-12 23:18:00,356] {base_job.py:229} ERROR - LocalTaskJob heartbeat got an exception
Traceback (most recent call last):
  File "/home/airflow/.local/lib/python3.7/site-packages/sqlalchemy/engine/base.py", line 3141, in _wrap_pool_connect
    return fn()
  File "/home/airflow/.local/lib/python3.7/site-packages/sqlalchemy/pool/base.py", line 301, in connect
    return _ConnectionFairy._checkout(self)
  File "/home/airflow/.local/lib/python3.7/site-packages/sqlalchemy/pool/base.py", line 755, in _checkout
    fairy = _ConnectionRecord.checkout(pool)
  File "/home/airflow/.local/lib/python3.7/site-packages/sqlalchemy/pool/base.py", line 419, in checkout
    rec = pool._do_get()
  File "/home/airflow/.local/lib/python3.7/site-packages/sqlalchemy/pool/impl.py", line 259, in _do_get
    return self._create_connection()
  File "/home/airflow/.local/lib/python3.7/site-packages/sqlalchemy/pool/base.py", line 247, in _create_connection
    return _ConnectionRecord(self)
  File "/home/airflow/.local/lib/python3.7/site-packages/sqlalchemy/pool/base.py", line 362, in __init__
    self.__connect(first_connect_check=True)
  File "/home/airflow/.local/lib/python3.7/site-packages/sqlalchemy/pool/base.py", line 605, in __connect
    pool.logger.debug("Error on connect(): %s", e)
  File "/home/airflow/.local/lib/python3.7/site-packages/sqlalchemy/util/langhelpers.py", line 72, in __exit__
    with_traceback=exc_tb,
  File "/home/airflow/.local/lib/python3.7/site-packages/sqlalchemy/util/compat.py", line 211, in raise_
    raise exception
  File "/home/airflow/.local/lib/python3.7/site-packages/sqlalchemy/pool/base.py", line 599, in __connect
    connection = pool._invoke_creator(self)
  File "/home/airflow/.local/lib/python3.7/site-packages/sqlalchemy/engine/create.py", line 578, in connect
    return dialect.connect(*cargs, **cparams)
  File "/home/airflow/.local/lib/python3.7/site-packages/sqlalchemy/engine/default.py", line 583, in connect
    return self.dbapi.connect(*cargs, **cparams)
  File "/home/airflow/.local/lib/python3.7/site-packages/psycopg2/__init__.py", line 122, in connect
    conn = _connect(dsn, connection_factory=connection_factory, **kwasync)
psycopg2.OperationalError: could not translate host name "postgres_***" to address: Temporary failure in name resolution


The above exception was the direct cause of the following exception:

Traceback (most recent call last):
  File "/home/airflow/.local/lib/python3.7/site-packages/airflow/jobs/base_job.py", line 201, in heartbeat
    session.merge(self)
  File "/home/airflow/.local/lib/python3.7/site-packages/sqlalchemy/orm/session.py", line 2877, in merge
    _resolve_conflict_map=_resolve_conflict_map,
  File "/home/airflow/.local/lib/python3.7/site-packages/sqlalchemy/orm/session.py", line 2950, in _merge
    merged = self.get(mapper.class_, key[1], identity_token=key[2])
  File "/home/airflow/.local/lib/python3.7/site-packages/sqlalchemy/orm/session.py", line 2702, in get
    identity_token=identity_token,
  File "/home/airflow/.local/lib/python3.7/site-packages/sqlalchemy/orm/session.py", line 2800, in _get_impl
    load_options=load_options,
  File "/home/airflow/.local/lib/python3.7/site-packages/sqlalchemy/orm/loading.py", line 535, in load_on_pk_identity
    bind_arguments=bind_arguments,
  File "/home/airflow/.local/lib/python3.7/site-packages/sqlalchemy/orm/session.py", line 1669, in execute
    conn = self._connection_for_bind(bind, close_with_result=True)
  File "/home/airflow/.local/lib/python3.7/site-packages/sqlalchemy/orm/session.py", line 1520, in _connection_for_bind
    engine, execution_options
  File "/home/airflow/.local/lib/python3.7/site-packages/sqlalchemy/orm/session.py", line 747, in _connection_for_bind
    conn = bind.connect()
  File "/home/airflow/.local/lib/python3.7/site-packages/sqlalchemy/engine/base.py", line 3095, in connect
    return self._connection_cls(self, close_with_result=close_with_result)
  File "/home/airflow/.local/lib/python3.7/site-packages/sqlalchemy/engine/base.py", line 91, in __init__
    else engine.raw_connection()
  File "/home/airflow/.local/lib/python3.7/site-packages/sqlalchemy/engine/base.py", line 3174, in raw_connection
    return self._wrap_pool_connect(self.pool.connect, _connection)
  File "/home/airflow/.local/lib/python3.7/site-packages/sqlalchemy/engine/base.py", line 3145, in _wrap_pool_connect
    e, dialect, self
  File "/home/airflow/.local/lib/python3.7/site-packages/sqlalchemy/engine/base.py", line 2004, in _handle_dbapi_exception_noconnection
    sqlalchemy_exception, with_traceback=exc_info[2], from_=e
  File "/home/airflow/.local/lib/python3.7/site-packages/sqlalchemy/util/compat.py", line 211, in raise_
    raise exception
  File "/home/airflow/.local/lib/python3.7/site-packages/sqlalchemy/engine/base.py", line 3141, in _wrap_pool_connect
    return fn()
  File "/home/airflow/.local/lib/python3.7/site-packages/sqlalchemy/pool/base.py", line 301, in connect
    return _ConnectionFairy._checkout(self)
  File "/home/airflow/.local/lib/python3.7/site-packages/sqlalchemy/pool/base.py", line 755, in _checkout
    fairy = _ConnectionRecord.checkout(pool)
  File "/home/airflow/.local/lib/python3.7/site-packages/sqlalchemy/pool/base.py", line 419, in checkout
    rec = pool._do_get()
  File "/home/airflow/.local/lib/python3.7/site-packages/sqlalchemy/pool/impl.py", line 259, in _do_get
    return self._create_connection()
  File "/home/airflow/.local/lib/python3.7/site-packages/sqlalchemy/pool/base.py", line 247, in _create_connection
    return _ConnectionRecord(self)
  File "/home/airflow/.local/lib/python3.7/site-packages/sqlalchemy/pool/base.py", line 362, in __init__
    self.__connect(first_connect_check=True)
  File "/home/airflow/.local/lib/python3.7/site-packages/sqlalchemy/pool/base.py", line 605, in __connect
    pool.logger.debug("Error on connect(): %s", e)
  File "/home/airflow/.local/lib/python3.7/site-packages/sqlalchemy/util/langhelpers.py", line 72, in __exit__
    with_traceback=exc_tb,
  File "/home/airflow/.local/lib/python3.7/site-packages/sqlalchemy/util/compat.py", line 211, in raise_
    raise exception
  File "/home/airflow/.local/lib/python3.7/site-packages/sqlalchemy/pool/base.py", line 599, in __connect
    connection = pool._invoke_creator(self)
  File "/home/airflow/.local/lib/python3.7/site-packages/sqlalchemy/engine/create.py", line 578, in connect
    return dialect.connect(*cargs, **cparams)
  File "/home/airflow/.local/lib/python3.7/site-packages/sqlalchemy/engine/default.py", line 583, in connect
    return self.dbapi.connect(*cargs, **cparams)
  File "/home/airflow/.local/lib/python3.7/site-packages/psycopg2/__init__.py", line 122, in connect
    conn = _connect(dsn, connection_factory=connection_factory, **kwasync)
sqlalchemy.exc.OperationalError: (psycopg2.OperationalError) could not translate host name "postgres_***" to address: Temporary failure in name resolution

(Background on this error at: http://sqlalche.me/e/14/e3q8)
[2022-06-12 23:18:42,844] {subprocess.py:92} INFO - [0m23:18:42  Running with dbt=1.1.0
[2022-06-12 23:18:42,859] {subprocess.py:92} INFO - [0m23:18:42  Partial parse save file not found. Starting full parse.
[2022-06-12 23:18:43,564] {subprocess.py:92} INFO - [0m23:18:43  [WARNING]: Configuration paths exist in your dbt_project.yml file which do not apply to any re***s.
[2022-06-12 23:18:43,564] {subprocess.py:92} INFO - There are 1 unused configuration paths:
[2022-06-12 23:18:43,564] {subprocess.py:92} INFO - - seeds.SAM
[2022-06-12 23:18:43,564] {subprocess.py:92} INFO - 
[2022-06-12 23:18:43,578] {subprocess.py:92} INFO - [0m23:18:43  Found 7 models, 6 tests, 0 snapshots, 0 analyses, 172 macros, 6 operations, 0 seed files, 4 ***s, 0 exposures, 0 metrics
[2022-06-12 23:18:43,581] {subprocess.py:92} INFO - [0m23:18:43
[2022-06-12 23:18:43,581] {subprocess.py:92} INFO - [0m23:18:43  [WARNING]: Nothing to do. Try checking your model configs and model specification args
[2022-06-12 23:18:43,587] {subprocess.py:92} INFO - [0m23:18:43
[2022-06-12 23:18:43,587] {subprocess.py:92} INFO - [0m23:18:43  Completed successfully
[2022-06-12 23:18:43,588] {subprocess.py:92} INFO - [0m23:18:43
[2022-06-12 23:18:43,588] {subprocess.py:92} INFO - [0m23:18:43  Done. PASS=0 WARN=0 ERROR=0 SKIP=0 TOTAL=0
[2022-06-12 23:18:46,627] {subprocess.py:92} INFO - [0m23:18:46  Running with dbt=1.1.0
[2022-06-12 23:18:46,660] {subprocess.py:92} INFO - [0m23:18:46  [WARNING]: Configuration paths exist in your dbt_project.yml file which do not apply to any re***s.
[2022-06-12 23:18:46,660] {subprocess.py:92} INFO - There are 1 unused configuration paths:
[2022-06-12 23:18:46,660] {subprocess.py:92} INFO - - seeds.SAM
[2022-06-12 23:18:46,660] {subprocess.py:92} INFO - 
[2022-06-12 23:18:46,677] {subprocess.py:92} INFO - [0m23:18:46  Found 7 models, 6 tests, 0 snapshots, 0 analyses, 172 macros, 6 operations, 0 seed files, 4 ***s, 0 exposures, 0 metrics
[2022-06-12 23:18:46,679] {subprocess.py:92} INFO - [0m23:18:46
[2022-06-12 23:18:46,748] {subprocess.py:92} INFO - [0m23:18:46  Concurrency: 4 threads (target='dev')
[2022-06-12 23:18:46,748] {subprocess.py:92} INFO - [0m23:18:46
[2022-06-12 23:18:46,756] {subprocess.py:92} INFO - [0m23:18:46  1 of 3 START table model analytics_dim.dim_date ................................ [RUN]
[2022-06-12 23:18:46,758] {subprocess.py:92} INFO - [0m23:18:46  2 of 3 START incremental model analytics_dim.dim_users ......................... [RUN]
[2022-06-12 23:18:46,759] {subprocess.py:92} INFO - [0m23:18:46  3 of 3 START incremental model analytics_dim.dim_walls ......................... [RUN]
[2022-06-12 23:18:46,968] {subprocess.py:92} INFO - [0m23:18:46  1 of 3 OK created table model analytics_dim.dim_date ........................... [SELECT 546 in 0.21s]
[2022-06-12 23:18:46,977] {subprocess.py:92} INFO - [0m23:18:46  2 of 3 OK created incremental model analytics_dim.dim_users .................... [INSERT 0 0 in 0.22s]
[2022-06-12 23:18:46,978] {subprocess.py:92} INFO - [0m23:18:46  3 of 3 OK created incremental model analytics_dim.dim_walls .................... [INSERT 0 0 in 0.22s]
[2022-06-12 23:18:47,071] {subprocess.py:92} INFO - [0m23:18:47
[2022-06-12 23:18:47,071] {subprocess.py:92} INFO - [0m23:18:47  Running 6 on-run-end hooks
[2022-06-12 23:18:47,079] {subprocess.py:92} INFO - [0m23:18:47  1 of 6 START hook: SAM.on-run-end.0 ............................................ [RUN]
[2022-06-12 23:18:47,082] {subprocess.py:92} INFO - [0m23:18:47  1 of 6 OK hook: SAM.on-run-end.0 ............................................... [ALTER DEFAULT PRIVILEGES in 0.00s]
[2022-06-12 23:18:47,086] {subprocess.py:92} INFO - [0m23:18:47  2 of 6 START hook: SAM.on-run-end.1 ............................................ [RUN]
[2022-06-12 23:18:47,089] {subprocess.py:92} INFO - [0m23:18:47  2 of 6 OK hook: SAM.on-run-end.1 ............................................... [ALTER DEFAULT PRIVILEGES in 0.00s]
[2022-06-12 23:18:47,093] {subprocess.py:92} INFO - [0m23:18:47  3 of 6 START hook: SAM.on-run-end.2 ............................................ [RUN]
[2022-06-12 23:18:47,096] {subprocess.py:92} INFO - [0m23:18:47  3 of 6 OK hook: SAM.on-run-end.2 ............................................... [ALTER DEFAULT PRIVILEGES in 0.00s]
[2022-06-12 23:18:47,099] {subprocess.py:92} INFO - [0m23:18:47  4 of 6 START hook: SAM.on-run-end.3 ............................................ [RUN]
[2022-06-12 23:18:47,102] {subprocess.py:92} INFO - [0m23:18:47  4 of 6 OK hook: SAM.on-run-end.3 ............................................... [ALTER DEFAULT PRIVILEGES in 0.00s]
[2022-06-12 23:18:47,105] {subprocess.py:92} INFO - [0m23:18:47  5 of 6 START hook: SAM.on-run-end.4 ............................................ [RUN]
[2022-06-12 23:18:47,108] {subprocess.py:92} INFO - [0m23:18:47  5 of 6 OK hook: SAM.on-run-end.4 ............................................... [ALTER DEFAULT PRIVILEGES in 0.00s]
[2022-06-12 23:18:47,111] {subprocess.py:92} INFO - [0m23:18:47  6 of 6 START hook: SAM.on-run-end.5 ............................................ [RUN]
[2022-06-12 23:18:47,113] {subprocess.py:92} INFO - [0m23:18:47  6 of 6 OK hook: SAM.on-run-end.5 ............................................... [ALTER DEFAULT PRIVILEGES in 0.00s]
[2022-06-12 23:18:47,115] {subprocess.py:92} INFO - [0m23:18:47
[2022-06-12 23:18:47,117] {subprocess.py:92} INFO - [0m23:18:47
[2022-06-12 23:18:47,117] {subprocess.py:92} INFO - [0m23:18:47  Finished running 1 table model, 2 incremental models, 6 hooks in 0.44s.
[2022-06-12 23:18:47,125] {subprocess.py:92} INFO - [0m23:18:47
[2022-06-12 23:18:47,126] {subprocess.py:92} INFO - [0m23:18:47  Completed successfully
[2022-06-12 23:18:47,126] {subprocess.py:92} INFO - [0m23:18:47
[2022-06-12 23:18:47,126] {subprocess.py:92} INFO - [0m23:18:47  Done. PASS=3 WARN=0 ERROR=0 SKIP=0 TOTAL=3
[2022-06-12 23:18:47,292] {subprocess.py:96} INFO - Command exited with return code 0
[2022-06-12 23:18:47,335] {taskinstance.py:1400} INFO - Marking task as SUCCESS. dag_id=T-dbt-job-dimensions, task_id=dbt_clone_and_transform-dimensions, execution_date=20220612T210930, start_date=20220612T231232, end_date=20220612T231847
[2022-06-12 23:18:47,358] {local_task_job.py:156} INFO - Task exited with return code 0
[2022-06-12 23:18:47,394] {local_task_job.py:273} INFO - 1 downstream tasks scheduled from follow-on schedule check
